time="2024-08-09T11:54:39Z" level=warning msg="/home/ubuntu/AEYE_AI/Docker/docker-compose.yml: the attribute `version` is obsolete, it will be ignored, please remove it to avoid potential confusion"
 Container network_operator_container  Created
 Container opticnet_container  Running
Attaching to network_operator_container, opticnet_container
network_operator_container  | Watching for file changes with StatReloader
network_operator_container  | Performing system checks...
network_operator_container  | 
network_operator_container  | System check identified no issues (0 silenced).
network_operator_container  | August 09, 2024 - 11:54:40
network_operator_container  | Django version 3.2, using settings 'AEYE_Network_Operator.settings'
network_operator_container  | Starting development server at http://0.0.0.0:3000/
network_operator_container  | Quit the server with CONTROL-C.
network_operator_container  | 
network_operator_container  | -----------------------------------------
network_operator_container  | 2024-08-09 11:54:43 [ Yoonchul ] send to : [94m[ NetOper API - ANO ][39m
network_operator_container  | [32m[active] received message  : Request AI Inference
network_operator_container  |          received operation: Inference[39m
network_operator_container  | -----------------------------------------
network_operator_container  | 
network_operator_container  | -----------------------------------------
network_operator_container  | 2024-08-09 11:54:43 [ NetOper API - ANO ] send to : [94m[ NetOper API - ANO ][39m
network_operator_container  | [32m[active] send data to : http://127.0.0.1:3000/mw/ai-inference/[39m
network_operator_container  | -----------------------------------------
network_operator_container  | Invalid HTTP_HOST header: '127.0.0.1:3000'. You may need to add '127.0.0.1' to ALLOWED_HOSTS.
network_operator_container  | Bad Request: /mw/ai-inference/
network_operator_container  | [09/Aug/2024 11:54:43] [31;1m"POST /mw/ai-inference/ HTTP/1.1" 400 60381[0m
network_operator_container  | Internal Server Error: /api/ai-network-operator/
network_operator_container  | Traceback (most recent call last):
network_operator_container  |   File "/usr/local/lib/python3.8/site-packages/django/core/handlers/exception.py", line 47, in inner
network_operator_container  |     response = get_response(request)
network_operator_container  |   File "/usr/local/lib/python3.8/site-packages/django/core/handlers/base.py", line 181, in _get_response
network_operator_container  |     response = wrapped_callback(request, *callback_args, **callback_kwargs)
network_operator_container  |   File "/usr/local/lib/python3.8/site-packages/django/views/decorators/csrf.py", line 54, in wrapped_view
network_operator_container  |     return view_func(*args, **kwargs)
network_operator_container  |   File "/usr/local/lib/python3.8/site-packages/rest_framework/viewsets.py", line 125, in view
network_operator_container  |     return self.dispatch(request, *args, **kwargs)
network_operator_container  |   File "/usr/local/lib/python3.8/site-packages/rest_framework/views.py", line 509, in dispatch
network_operator_container  |     response = self.handle_exception(exc)
network_operator_container  |   File "/usr/local/lib/python3.8/site-packages/rest_framework/views.py", line 469, in handle_exception
network_operator_container  |     self.raise_uncaught_exception(exc)
network_operator_container  |   File "/usr/local/lib/python3.8/site-packages/rest_framework/views.py", line 480, in raise_uncaught_exception
network_operator_container  |     raise exc
network_operator_container  |   File "/usr/local/lib/python3.8/site-packages/rest_framework/views.py", line 506, in dispatch
network_operator_container  |     response = handler(request, *args, **kwargs)
network_operator_container  |   File "/app/api/views/AEYE_ANO.py", line 53, in create
network_operator_container  |     response_from_server = loop.run_until_complete(aeye_ai_inference_request(image, url))
network_operator_container  |   File "/usr/local/lib/python3.8/asyncio/base_events.py", line 616, in run_until_complete
network_operator_container  |     return future.result()
network_operator_container  |   File "/app/api/views/AEYE_ANO.py", line 94, in aeye_ai_inference_request
network_operator_container  |     result_from_server = await response_from_server
network_operator_container  | TypeError: object ClientResponse can't be used in 'await' expression
network_operator_container  | [09/Aug/2024 11:54:43] [35;1m"POST /api/ai-network-operator/ HTTP/1.1" 500 95665[0m
network_operator_container  | /app/AEYE_Network_Operator/settings.py changed, reloading.
network_operator_container  | [0mWatching for file changes with StatReloader
network_operator_container  | Performing system checks...
network_operator_container  | 
network_operator_container  | System check identified no issues (0 silenced).
network_operator_container  | August 09, 2024 - 11:55:13
network_operator_container  | Django version 3.2, using settings 'AEYE_Network_Operator.settings'
network_operator_container  | Starting development server at http://0.0.0.0:3000/
network_operator_container  | Quit the server with CONTROL-C.
network_operator_container  | 
network_operator_container  | -----------------------------------------
network_operator_container  | 2024-08-09 11:55:16 [ Yoonchul ] send to : [94m[ NetOper API - ANO ][39m
network_operator_container  | [32m[active] received message  : Request AI Inference
network_operator_container  |          received operation: Inference[39m
network_operator_container  | -----------------------------------------
network_operator_container  | 
network_operator_container  | -----------------------------------------
network_operator_container  | 2024-08-09 11:55:16 [ NetOper API - ANO ] send to : [94m[ NetOper API - ANO ][39m
network_operator_container  | [32m[active] send data to : http://127.0.0.1:3000/mw/ai-inference/[39m
network_operator_container  | -----------------------------------------
network_operator_container  | 
network_operator_container  | -----------------------------------------
network_operator_container  | 2024-08-09 11:55:16 [ NetOper API - ANO ] Send to : [94m[ NetOper MW - Inference ][39m
network_operator_container  | [32m[active] [32mMW - Inference received message : Request AI Inference [39m
network_operator_container  | -----------------------------------------
network_operator_container  | 
network_operator_container  | -----------------------------------------
network_operator_container  | 2024-08-09 11:55:16 [ NetOper MW - Inference ] Send to : [94m[ NetOper MW - Inference ][39m
network_operator_container  | [32m[active] [32mcheck server status : http://opticnet_container:2000/api/start-upload-file/ [39m
network_operator_container  | -----------------------------------------
opticnet_container          | INFO:root:
opticnet_container          | -----------------------------------------
opticnet_container          | 2024-08-09 11:55:16 [ NetOper MW - Inference ] send to: [34m[ OpticNet - API UCTC ]
opticnet_container          | [39m[32m[OpticNet - active] [39mmessage: [ [32mNetOper MW - Inference received valid from OpticNet - API UCTC ][39m
opticnet_container          | -----------------------------------------
opticnet_container          | INFO:werkzeug:172.18.0.3 - - [09/Aug/2024 11:55:16] "[37mPOST /api/start-upload-file/ HTTP/1.1[0m" 200 -
network_operator_container  | 
network_operator_container  | -----------------------------------------
network_operator_container  | 2024-08-09 11:55:16 [ NetOper MW - Inference ] Send to : [94m[ NetOper MW - Inference ][39m
network_operator_container  | [32m[active] [32mserver is ok : http://opticnet_container:2000/api/start-upload-file/ [39m
network_operator_container  | -----------------------------------------
opticnet_container          | INFO:werkzeug:172.18.0.3 - - [09/Aug/2024 11:55:16] "[37mPOST /api/upload-file-chunk/ HTTP/1.1[0m" 200 -
opticnet_container          | INFO:werkzeug:172.18.0.3 - - [09/Aug/2024 11:55:16] "[37mPOST /api/data-assemble/ HTTP/1.1[0m" 200 -
network_operator_container  | Internal Server Error: /mw/ai-inference/
network_operator_container  | Traceback (most recent call last):
network_operator_container  |   File "/usr/local/lib/python3.8/site-packages/django/core/handlers/exception.py", line 47, in inner
network_operator_container  |     response = get_response(request)
network_operator_container  |   File "/usr/local/lib/python3.8/site-packages/django/core/handlers/base.py", line 181, in _get_response
network_operator_container  |     response = wrapped_callback(request, *callback_args, **callback_kwargs)
network_operator_container  |   File "/usr/local/lib/python3.8/site-packages/django/views/decorators/csrf.py", line 54, in wrapped_view
network_operator_container  |     return view_func(*args, **kwargs)
network_operator_container  |   File "/usr/local/lib/python3.8/site-packages/rest_framework/viewsets.py", line 125, in view
network_operator_container  |     return self.dispatch(request, *args, **kwargs)
network_operator_container  |   File "/usr/local/lib/python3.8/site-packages/rest_framework/views.py", line 509, in dispatch
network_operator_container  |     response = self.handle_exception(exc)
network_operator_container  |   File "/usr/local/lib/python3.8/site-packages/rest_framework/views.py", line 469, in handle_exception
network_operator_container  |     self.raise_uncaught_exception(exc)
network_operator_container  |   File "/usr/local/lib/python3.8/site-packages/rest_framework/views.py", line 480, in raise_uncaught_exception
network_operator_container  |     raise exc
network_operator_container  |   File "/usr/local/lib/python3.8/site-packages/rest_framework/views.py", line 506, in dispatch
network_operator_container  |     response = handler(request, *args, **kwargs)
network_operator_container  |   File "/app/mw/views/AEYE_Inference.py", line 57, in create
network_operator_container  |     response_from_server = aeye_ai_inference_request(image)
network_operator_container  |   File "/app/mw/views/AEYE_Inference.py", line 175, in aeye_ai_inference_request
network_operator_container  |     response_weight = aeye_upload_data(h5_file_path, chunk_size=chunk_size)
network_operator_container  |   File "/app/mw/views/AEYE_Inference.py", line 75, in aeye_upload_data
network_operator_container  |     file_size = os.path.getsize(file_path)
network_operator_container  |   File "/usr/local/lib/python3.8/genericpath.py", line 50, in getsize
network_operator_container  |     return os.stat(filename).st_size
network_operator_container  | FileNotFoundError: [Errno 2] No such file or directory: '/app/mw/views/weight/Srinivasan2014.h5'
network_operator_container  | [09/Aug/2024 11:55:16] [35;1m"POST /mw/ai-inference/ HTTP/1.1" 500 97492[0m
network_operator_container  | [09/Aug/2024 11:55:16,340] - Broken pipe from ('127.0.0.1', 41212)
network_operator_container  | 
network_operator_container  | Internal Server Error: /api/ai-network-operator/
network_operator_container  | Traceback (most recent call last):
network_operator_container  |   File "/usr/local/lib/python3.8/site-packages/django/core/handlers/exception.py", line 47, in inner
network_operator_container  |     response = get_response(request)
network_operator_container  |   File "/usr/local/lib/python3.8/site-packages/django/core/handlers/base.py", line 181, in _get_response
network_operator_container  |     response = wrapped_callback(request, *callback_args, **callback_kwargs)
network_operator_container  |   File "/usr/local/lib/python3.8/site-packages/django/views/decorators/csrf.py", line 54, in wrapped_view
network_operator_container  |     return view_func(*args, **kwargs)
network_operator_container  |   File "/usr/local/lib/python3.8/site-packages/rest_framework/viewsets.py", line 125, in view
network_operator_container  |     return self.dispatch(request, *args, **kwargs)
network_operator_container  |   File "/usr/local/lib/python3.8/site-packages/rest_framework/views.py", line 509, in dispatch
network_operator_container  |     response = self.handle_exception(exc)
network_operator_container  |   File "/usr/local/lib/python3.8/site-packages/rest_framework/views.py", line 469, in handle_exception
network_operator_container  |     self.raise_uncaught_exception(exc)
network_operator_container  |   File "/usr/local/lib/python3.8/site-packages/rest_framework/views.py", line 480, in raise_uncaught_exception
network_operator_container  |     raise exc
network_operator_container  |   File "/usr/local/lib/python3.8/site-packages/rest_framework/views.py", line 506, in dispatch
network_operator_container  |     response = handler(request, *args, **kwargs)
network_operator_container  |   File "/app/api/views/AEYE_ANO.py", line 53, in create
network_operator_container  |     response_from_server = loop.run_until_complete(aeye_ai_inference_request(image, url))
network_operator_container  |   File "/usr/local/lib/python3.8/asyncio/base_events.py", line 616, in run_until_complete
network_operator_container  |     return future.result()
network_operator_container  |   File "/app/api/views/AEYE_ANO.py", line 94, in aeye_ai_inference_request
network_operator_container  |     result_from_server = await response_from_server
network_operator_container  | TypeError: object ClientResponse can't be used in 'await' expression
network_operator_container  | [09/Aug/2024 11:55:16] [35;1m"POST /api/ai-network-operator/ HTTP/1.1" 500 95749[0m
