time="2024-08-06T01:28:52+09:00" level=warning msg="/home/yoonchcul/Documents/Hanium_2024/AEYE_AI/develop/Docker/docker-compose.yml: the attribute `version` is obsolete, it will be ignored, please remove it to avoid potential confusion"
 AEYE-NetOper Pulling 
 AEYE-OpticNet Pulling 
 AEYE-OpticNet Warning pull access denied for aeye_opticnet, repository does not exist or may require 'docker login': denied: requested access to the resource is denied
 AEYE-NetOper Warning pull access denied for aeye_network_operator, repository does not exist or may require 'docker login': denied: requested access to the resource is denied
#0 building with "default" instance using docker driver

#1 [AEYE-OpticNet internal] load build definition from Dockerfile
#1 transferring dockerfile: 1.34kB done
#1 DONE 0.0s

#2 [AEYE-NetOper internal] load build definition from Dockerfile
#2 transferring dockerfile: 1.04kB done
#2 DONE 0.0s

#3 [AEYE-NetOper internal] load metadata for docker.io/library/python:3.8-slim
#3 ...

#4 [AEYE-OpticNet internal] load metadata for docker.io/tensorflow/tensorflow:1.12.0-rc1-gpu-py3
#4 DONE 1.2s

#3 [AEYE-NetOper internal] load metadata for docker.io/library/python:3.8-slim
#3 DONE 1.2s

#5 [AEYE-OpticNet internal] load .dockerignore
#5 transferring context: 2B done
#5 DONE 0.0s

#6 [AEYE-OpticNet  1/13] FROM docker.io/tensorflow/tensorflow:1.12.0-rc1-gpu-py3@sha256:ed8122324df71ddaf144bfc81b99fd8d439ea105f1879ece23a2279d04351722
#6 DONE 0.0s

#7 [AEYE-NetOper internal] load .dockerignore
#7 transferring context: 2B done
#7 DONE 0.0s

#8 [AEYE-NetOper 1/8] FROM docker.io/library/python:3.8-slim@sha256:3c4f18300d05e17aa08023b1a5ac4d6d1dd2ec42709ccdcbc3a53e3e36e0e4ea
#8 DONE 0.0s

#9 [AEYE-NetOper internal] load build context
#9 transferring context: 9.06kB done
#9 DONE 0.0s

#10 [AEYE-NetOper 5/8] RUN pip install --upgrade pip
#10 CACHED

#11 [AEYE-NetOper 7/8] WORKDIR /app/
#11 CACHED

#12 [AEYE-NetOper 4/8] RUN apt-get update && apt-get install -y     build-essential     libpq-dev     && apt-get clean     && rm -rf /var/lib/apt/lists/*
#12 CACHED

#13 [AEYE-NetOper 6/8] RUN pip install -r dependencies.txt
#13 CACHED

#14 [AEYE-NetOper 2/8] WORKDIR /app
#14 CACHED

#15 [AEYE-NetOper 3/8] COPY /Docker/AEYE_Network_Operator/dependencies.txt /app/
#15 CACHED

#16 [AEYE-NetOper 8/8] COPY /AEYE_Network_Operator/ /app/
#16 CACHED

#17 [AEYE-NetOper] exporting to image
#17 exporting layers done
#17 writing image sha256:f8e3ffea321a66caf09622adba8e4227be8f7652c3a6c9ea0e789bcd6b12f21b done
#17 naming to docker.io/library/aeye_network_operator:1.0 done
#17 DONE 0.0s

#18 [AEYE-OpticNet internal] load build context
#18 transferring context: 202.08kB 0.0s done
#18 DONE 0.1s

#19 [AEYE-OpticNet 12/13] COPY /Docker/AEYE_AI/dependencies.txt /app/AEYE_AI
#19 CACHED

#20 [AEYE-OpticNet  2/13] RUN pip install keras==2.2.4
#20 CACHED

#21 [AEYE-OpticNet  3/13] RUN pip install pycm==1.9 matplotlib sklearn
#21 CACHED

#22 [AEYE-OpticNet 10/13] WORKDIR /app/AEYE_AI
#22 CACHED

#23 [AEYE-OpticNet  5/13] RUN pip install opencv-python
#23 CACHED

#24 [AEYE-OpticNet  6/13] RUN pip install Flask==1.1.4
#24 CACHED

#25 [AEYE-OpticNet  4/13] RUN pip install --upgrade pip
#25 CACHED

#26 [AEYE-OpticNet 11/13] COPY /AEYE_AI/ /app/AEYE_AI/
#26 CACHED

#27 [AEYE-OpticNet  8/13] RUN apt-get update
#27 CACHED

#28 [AEYE-OpticNet  9/13] RUN apt-get install -y libgl1-mesa-glx --fix-missing
#28 CACHED

#29 [AEYE-OpticNet  7/13] RUN pip install colorama
#29 CACHED

#30 [AEYE-OpticNet 13/13] RUN pip install -r dependencies.txt
#30 CACHED

#31 [AEYE-OpticNet] exporting to image
#31 exporting layers done
#31 writing image sha256:e9ee6dca158068884a2ac94cea415d3bf5f67ae6084270fbf8ea7c4caa9c4bdf done
#31 naming to docker.io/library/aeye_opticnet:1.0 done
#31 DONE 0.0s

#32 [AEYE-NetOper] resolving provenance for metadata file
#32 DONE 0.0s

#33 [AEYE-OpticNet] resolving provenance for metadata file
#33 DONE 0.0s
 Container network_operator_container  Recreate
 Container opticnet_container  Recreate
 Container opticnet_container  Recreated
 Container network_operator_container  Recreated
Attaching to network_operator_container, opticnet_container
network_operator_container  | Watching for file changes with StatReloader
network_operator_container  | Performing system checks...
network_operator_container  | 
network_operator_container  | System check identified no issues (0 silenced).
network_operator_container  | August 05, 2024 - 16:28:58
network_operator_container  | Django version 3.2, using settings 'AEYE_Network_Operator.settings'
network_operator_container  | Starting development server at http://0.0.0.0:3000/
network_operator_container  | Quit the server with CONTROL-C.
opticnet_container          |  * Serving Flask app "AEYE" (lazy loading)
opticnet_container          |  * Environment: production
opticnet_container          |    WARNING: This is a development server. Do not use it in a production deployment.
opticnet_container          |    Use a production WSGI server instead.
opticnet_container          |  * Debug mode: on
opticnet_container          | Using TensorFlow backend.
opticnet_container          |  * Running on http://0.0.0.0:2000/ (Press CTRL+C to quit)
opticnet_container          |  * Restarting with stat
opticnet_container          | Using TensorFlow backend.
opticnet_container          |  * Debugger is active!
opticnet_container          |  * Debugger PIN: 273-217-641
opticnet_container          | 172.18.0.1 - - [05/Aug/2024 16:29:03] "[33mGET / HTTP/1.1[0m" 404 -
opticnet_container          | 172.18.0.1 - - [05/Aug/2024 16:29:04] "[33mGET / HTTP/1.1[0m" 404 -
opticnet_container          | 172.18.0.1 - - [05/Aug/2024 16:29:05] "[33mGET / HTTP/1.1[0m" 404 -
opticnet_container          | 172.18.0.1 - - [05/Aug/2024 16:29:07] "[33mGET / HTTP/1.1[0m" 404 -
opticnet_container          | 172.18.0.1 - - [05/Aug/2024 16:29:08] "[33mGET / HTTP/1.1[0m" 404 -
network_operator_container  | 
network_operator_container  | -----------------------------------------
network_operator_container  | 2024-08-05 16:29:39 Yoonchul[ API - ANO ]
network_operator_container  | [AI NetOper - active] message: [ Received Valid Data : Request AI Inference ]
network_operator_container  | -----------------------------------------
network_operator_container  | Internal Server Error: /api/ai-network-operator/
network_operator_container  | Traceback (most recent call last):
network_operator_container  |   File "/usr/local/lib/python3.8/site-packages/django/core/handlers/exception.py", line 47, in inner
network_operator_container  |     response = get_response(request)
network_operator_container  |   File "/usr/local/lib/python3.8/site-packages/django/core/handlers/base.py", line 181, in _get_response
network_operator_container  |     response = wrapped_callback(request, *callback_args, **callback_kwargs)
network_operator_container  |   File "/usr/local/lib/python3.8/site-packages/django/views/decorators/csrf.py", line 54, in wrapped_view
network_operator_container  |     return view_func(*args, **kwargs)
network_operator_container  |   File "/usr/local/lib/python3.8/site-packages/rest_framework/viewsets.py", line 125, in view
network_operator_container  |     return self.dispatch(request, *args, **kwargs)
network_operator_container  |   File "/usr/local/lib/python3.8/site-packages/rest_framework/views.py", line 509, in dispatch
network_operator_container  |     response = self.handle_exception(exc)
network_operator_container  |   File "/usr/local/lib/python3.8/site-packages/rest_framework/views.py", line 469, in handle_exception
network_operator_container  |     self.raise_uncaught_exception(exc)
network_operator_container  |   File "/usr/local/lib/python3.8/site-packages/rest_framework/views.py", line 480, in raise_uncaught_exception
network_operator_container  |     raise exc
network_operator_container  |   File "/usr/local/lib/python3.8/site-packages/rest_framework/views.py", line 506, in dispatch
network_operator_container  |     response = handler(request, *args, **kwargs)
network_operator_container  |   File "/app/api/views/AEYE_ANO.py", line 46, in create
network_operator_container  |     response = aeye_ai_inference_request(image, url)
network_operator_container  |   File "/app/api/views/AEYE_ANO.py", line 72, in aeye_ai_inference_request
network_operator_container  |     files = {'image': (image.name, image.read(), image.content_type)}
network_operator_container  | AttributeError: 'NoneType' object has no attribute 'name'
network_operator_container  | [05/Aug/2024 16:29:39] "POST /api/ai-network-operator/ HTTP/1.1" 500 88570
network_operator_container  | 
network_operator_container  | -----------------------------------------
network_operator_container  | 2024-08-05 16:30:09 Yoonchul[ API - ANO ]
network_operator_container  | [AI NetOper - active] message: [ Received Valid Data : Request AI Inference ]
network_operator_container  | -----------------------------------------
network_operator_container  | Internal Server Error: /api/ai-network-operator/
network_operator_container  | Traceback (most recent call last):
network_operator_container  |   File "/usr/local/lib/python3.8/site-packages/django/core/handlers/exception.py", line 47, in inner
network_operator_container  |     response = get_response(request)
network_operator_container  |   File "/usr/local/lib/python3.8/site-packages/django/core/handlers/base.py", line 181, in _get_response
network_operator_container  |     response = wrapped_callback(request, *callback_args, **callback_kwargs)
network_operator_container  |   File "/usr/local/lib/python3.8/site-packages/django/views/decorators/csrf.py", line 54, in wrapped_view
network_operator_container  |     return view_func(*args, **kwargs)
network_operator_container  |   File "/usr/local/lib/python3.8/site-packages/rest_framework/viewsets.py", line 125, in view
network_operator_container  |     return self.dispatch(request, *args, **kwargs)
network_operator_container  |   File "/usr/local/lib/python3.8/site-packages/rest_framework/views.py", line 509, in dispatch
network_operator_container  |     response = self.handle_exception(exc)
network_operator_container  |   File "/usr/local/lib/python3.8/site-packages/rest_framework/views.py", line 469, in handle_exception
network_operator_container  |     self.raise_uncaught_exception(exc)
network_operator_container  |   File "/usr/local/lib/python3.8/site-packages/rest_framework/views.py", line 480, in raise_uncaught_exception
network_operator_container  |     raise exc
network_operator_container  |   File "/usr/local/lib/python3.8/site-packages/rest_framework/views.py", line 506, in dispatch
network_operator_container  |     response = handler(request, *args, **kwargs)
network_operator_container  |   File "/app/api/views/AEYE_ANO.py", line 46, in create
network_operator_container  |     response = aeye_ai_inference_request(image, url)
network_operator_container  |   File "/app/api/views/AEYE_ANO.py", line 77, in aeye_ai_inference_request
network_operator_container  |     response = requests.post(url, data=data, files=files)
network_operator_container  |   File "/usr/local/lib/python3.8/site-packages/requests/api.py", line 115, in post
network_operator_container  |     return request("post", url, data=data, json=json, **kwargs)
network_operator_container  |   File "/usr/local/lib/python3.8/site-packages/requests/api.py", line 59, in request
network_operator_container  |     return session.request(method=method, url=url, **kwargs)
network_operator_container  |   File "/usr/local/lib/python3.8/site-packages/requests/sessions.py", line 589, in request
network_operator_container  |     resp = self.send(prep, **send_kwargs)
network_operator_container  |   File "/usr/local/lib/python3.8/site-packages/requests/sessions.py", line 697, in send
network_operator_container  |     adapter = self.get_adapter(url=request.url)
network_operator_container  |   File "/usr/local/lib/python3.8/site-packages/requests/sessions.py", line 792, in get_adapter
network_operator_container  |     raise InvalidSchema(f"No connection adapters were found for {url!r}")
network_operator_container  | requests.exceptions.InvalidSchema: No connection adapters were found for '127.0.0.1:3000/mw/ai-inference/'
network_operator_container  | [05/Aug/2024 16:30:09] "POST /api/ai-network-operator/ HTTP/1.1" 500 133206
network_operator_container  | Bad Request: /mw/ai-inference/
network_operator_container  | [05/Aug/2024 16:34:25] "POST /mw/ai-inference/ HTTP/1.1" 400 75
network_operator_container  | Bad Request: /mw/ai-inference/
network_operator_container  | [05/Aug/2024 16:35:01] "POST /mw/ai-inference/ HTTP/1.1" 400 75
opticnet_container          |  * Detected change in '/app/AEYE_AI/AEYE_HAL/AEYE_Inference.py', reloading
opticnet_container          |  * Restarting with stat
opticnet_container          | Using TensorFlow backend.
opticnet_container          |  * Debugger is active!
opticnet_container          |  * Debugger PIN: 273-217-641
opticnet_container          |  * Detected change in '/app/AEYE_AI/AEYE_HAL/AEYE_Inference.py', reloading
opticnet_container          |  * Restarting with stat
opticnet_container          | Using TensorFlow backend.
opticnet_container          |  * Debugger is active!
opticnet_container          |  * Debugger PIN: 273-217-641
network_operator_container  | Bad Request: /mw/ai-inference/
network_operator_container  | [05/Aug/2024 16:36:12] "POST /mw/ai-inference/ HTTP/1.1" 400 75
network_operator_container  | 
network_operator_container  | -----------------------------------------
network_operator_container  | 2024-08-05 16:36:16 Yoonchul[ API - ANO ]
network_operator_container  | [AI NetOper - active] message: [ Received Valid Data : Request AI Inference ]
network_operator_container  | -----------------------------------------
network_operator_container  | Internal Server Error: /api/ai-network-operator/
network_operator_container  | Traceback (most recent call last):
network_operator_container  |   File "/usr/local/lib/python3.8/site-packages/django/core/handlers/exception.py", line 47, in inner
network_operator_container  |     response = get_response(request)
network_operator_container  |   File "/usr/local/lib/python3.8/site-packages/django/core/handlers/base.py", line 181, in _get_response
network_operator_container  |     response = wrapped_callback(request, *callback_args, **callback_kwargs)
network_operator_container  |   File "/usr/local/lib/python3.8/site-packages/django/views/decorators/csrf.py", line 54, in wrapped_view
network_operator_container  |     return view_func(*args, **kwargs)
network_operator_container  |   File "/usr/local/lib/python3.8/site-packages/rest_framework/viewsets.py", line 125, in view
network_operator_container  |     return self.dispatch(request, *args, **kwargs)
network_operator_container  |   File "/usr/local/lib/python3.8/site-packages/rest_framework/views.py", line 509, in dispatch
network_operator_container  |     response = self.handle_exception(exc)
network_operator_container  |   File "/usr/local/lib/python3.8/site-packages/rest_framework/views.py", line 469, in handle_exception
network_operator_container  |     self.raise_uncaught_exception(exc)
network_operator_container  |   File "/usr/local/lib/python3.8/site-packages/rest_framework/views.py", line 480, in raise_uncaught_exception
network_operator_container  |     raise exc
network_operator_container  |   File "/usr/local/lib/python3.8/site-packages/rest_framework/views.py", line 506, in dispatch
network_operator_container  |     response = handler(request, *args, **kwargs)
network_operator_container  |   File "/app/api/views/AEYE_ANO.py", line 46, in create
network_operator_container  |     response = aeye_ai_inference_request(image, url)
network_operator_container  |   File "/app/api/views/AEYE_ANO.py", line 77, in aeye_ai_inference_request
network_operator_container  |     response = requests.post(url, data=data, files=files)
network_operator_container  |   File "/usr/local/lib/python3.8/site-packages/requests/api.py", line 115, in post
network_operator_container  |     return request("post", url, data=data, json=json, **kwargs)
network_operator_container  |   File "/usr/local/lib/python3.8/site-packages/requests/api.py", line 59, in request
network_operator_container  |     return session.request(method=method, url=url, **kwargs)
network_operator_container  |   File "/usr/local/lib/python3.8/site-packages/requests/sessions.py", line 589, in request
network_operator_container  |     resp = self.send(prep, **send_kwargs)
network_operator_container  |   File "/usr/local/lib/python3.8/site-packages/requests/sessions.py", line 697, in send
network_operator_container  |     adapter = self.get_adapter(url=request.url)
network_operator_container  |   File "/usr/local/lib/python3.8/site-packages/requests/sessions.py", line 792, in get_adapter
network_operator_container  |     raise InvalidSchema(f"No connection adapters were found for {url!r}")
network_operator_container  | requests.exceptions.InvalidSchema: No connection adapters were found for '127.0.0.1:3000/mw/ai-inference/'
network_operator_container  | [05/Aug/2024 16:36:16] "POST /api/ai-network-operator/ HTTP/1.1" 500 133206
opticnet_container          |  * Detected change in '/app/AEYE_AI/AEYE_HAL/AEYE_Inference.py', reloading
opticnet_container          |  * Restarting with stat
opticnet_container          | Using TensorFlow backend.
opticnet_container          |  * Debugger is active!
opticnet_container          |  * Debugger PIN: 273-217-641
network_operator_container  | 
network_operator_container  | -----------------------------------------
network_operator_container  | 2024-08-05 16:37:18 Yoonchul[ API - ANO ]
network_operator_container  | [AI NetOper - active] message: [ Received Valid Data : Request AI Inference ]
network_operator_container  | -----------------------------------------
network_operator_container  | Internal Server Error: /api/ai-network-operator/
network_operator_container  | Traceback (most recent call last):
network_operator_container  |   File "/usr/local/lib/python3.8/site-packages/django/core/handlers/exception.py", line 47, in inner
network_operator_container  |     response = get_response(request)
network_operator_container  |   File "/usr/local/lib/python3.8/site-packages/django/core/handlers/base.py", line 181, in _get_response
network_operator_container  |     response = wrapped_callback(request, *callback_args, **callback_kwargs)
network_operator_container  |   File "/usr/local/lib/python3.8/site-packages/django/views/decorators/csrf.py", line 54, in wrapped_view
network_operator_container  |     return view_func(*args, **kwargs)
network_operator_container  |   File "/usr/local/lib/python3.8/site-packages/rest_framework/viewsets.py", line 125, in view
network_operator_container  |     return self.dispatch(request, *args, **kwargs)
network_operator_container  |   File "/usr/local/lib/python3.8/site-packages/rest_framework/views.py", line 509, in dispatch
network_operator_container  |     response = self.handle_exception(exc)
network_operator_container  |   File "/usr/local/lib/python3.8/site-packages/rest_framework/views.py", line 469, in handle_exception
network_operator_container  |     self.raise_uncaught_exception(exc)
network_operator_container  |   File "/usr/local/lib/python3.8/site-packages/rest_framework/views.py", line 480, in raise_uncaught_exception
network_operator_container  |     raise exc
network_operator_container  |   File "/usr/local/lib/python3.8/site-packages/rest_framework/views.py", line 506, in dispatch
network_operator_container  |     response = handler(request, *args, **kwargs)
network_operator_container  |   File "/app/api/views/AEYE_ANO.py", line 46, in create
network_operator_container  |     response = aeye_ai_inference_request(image, url)
network_operator_container  |   File "/app/api/views/AEYE_ANO.py", line 77, in aeye_ai_inference_request
network_operator_container  |     response = requests.post(url, data=data, files=files)
network_operator_container  |   File "/usr/local/lib/python3.8/site-packages/requests/api.py", line 115, in post
network_operator_container  |     return request("post", url, data=data, json=json, **kwargs)
network_operator_container  |   File "/usr/local/lib/python3.8/site-packages/requests/api.py", line 59, in request
network_operator_container  |     return session.request(method=method, url=url, **kwargs)
network_operator_container  |   File "/usr/local/lib/python3.8/site-packages/requests/sessions.py", line 589, in request
network_operator_container  |     resp = self.send(prep, **send_kwargs)
network_operator_container  |   File "/usr/local/lib/python3.8/site-packages/requests/sessions.py", line 697, in send
network_operator_container  |     adapter = self.get_adapter(url=request.url)
network_operator_container  |   File "/usr/local/lib/python3.8/site-packages/requests/sessions.py", line 792, in get_adapter
network_operator_container  |     raise InvalidSchema(f"No connection adapters were found for {url!r}")
network_operator_container  | requests.exceptions.InvalidSchema: No connection adapters were found for '127.0.0.1:3000/mw/ai-inference/'
network_operator_container  | [05/Aug/2024 16:37:18] "POST /api/ai-network-operator/ HTTP/1.1" 500 133206
network_operator_container  | Bad Request: /mw/ai-inference/
network_operator_container  | [05/Aug/2024 16:38:23] "POST /mw/ai-inference/ HTTP/1.1" 400 75
network_operator_container  | /app/api/views/AEYE_ANO.py changed, reloading.
network_operator_container  | Watching for file changes with StatReloader
network_operator_container  | Performing system checks...
network_operator_container  | 
network_operator_container  | System check identified no issues (0 silenced).
network_operator_container  | August 05, 2024 - 16:38:58
network_operator_container  | Django version 3.2, using settings 'AEYE_Network_Operator.settings'
network_operator_container  | Starting development server at http://0.0.0.0:3000/
network_operator_container  | Quit the server with CONTROL-C.
network_operator_container  | /app/api/views/AEYE_ANO.py changed, reloading.
network_operator_container  | Watching for file changes with StatReloader
network_operator_container  | Performing system checks...
network_operator_container  | 
network_operator_container  | System check identified no issues (0 silenced).
network_operator_container  | August 05, 2024 - 16:39:15
network_operator_container  | Django version 3.2, using settings 'AEYE_Network_Operator.settings'
network_operator_container  | Starting development server at http://0.0.0.0:3000/
network_operator_container  | Quit the server with CONTROL-C.
network_operator_container  | 
network_operator_container  | -----------------------------------------
network_operator_container  | 2024-08-05 16:39:17 Yoonchul[ API - ANO ]
network_operator_container  | [AI NetOper - active] message: [ Received Valid Data : Request AI Inference ]
network_operator_container  | -----------------------------------------
network_operator_container  | Internal Server Error: /api/ai-network-operator/
network_operator_container  | Traceback (most recent call last):
network_operator_container  |   File "/usr/local/lib/python3.8/site-packages/django/core/handlers/exception.py", line 47, in inner
network_operator_container  |     response = get_response(request)
network_operator_container  |   File "/usr/local/lib/python3.8/site-packages/django/core/handlers/base.py", line 181, in _get_response
network_operator_container  |     response = wrapped_callback(request, *callback_args, **callback_kwargs)
network_operator_container  |   File "/usr/local/lib/python3.8/site-packages/django/views/decorators/csrf.py", line 54, in wrapped_view
network_operator_container  |     return view_func(*args, **kwargs)
network_operator_container  |   File "/usr/local/lib/python3.8/site-packages/rest_framework/viewsets.py", line 125, in view
network_operator_container  |     return self.dispatch(request, *args, **kwargs)
network_operator_container  |   File "/usr/local/lib/python3.8/site-packages/rest_framework/views.py", line 509, in dispatch
network_operator_container  |     response = self.handle_exception(exc)
network_operator_container  |   File "/usr/local/lib/python3.8/site-packages/rest_framework/views.py", line 469, in handle_exception
network_operator_container  |     self.raise_uncaught_exception(exc)
network_operator_container  |   File "/usr/local/lib/python3.8/site-packages/rest_framework/views.py", line 480, in raise_uncaught_exception
network_operator_container  |     raise exc
network_operator_container  |   File "/usr/local/lib/python3.8/site-packages/rest_framework/views.py", line 506, in dispatch
network_operator_container  |     response = handler(request, *args, **kwargs)
network_operator_container  |   File "/app/api/views/AEYE_ANO.py", line 46, in create
network_operator_container  |     response = aeye_ai_inference_request(image, url)
network_operator_container  |   File "/app/api/views/AEYE_ANO.py", line 76, in aeye_ai_inference_request
network_operator_container  |     print_log('active', whoami, api, "Send Data to : {}".format(url))
network_operator_container  | UnboundLocalError: local variable 'whoami' referenced before assignment
network_operator_container  | [05/Aug/2024 16:39:17] "POST /api/ai-network-operator/ HTTP/1.1" 500 94306
network_operator_container  | /app/api/views/AEYE_ANO.py changed, reloading.
network_operator_container  | Watching for file changes with StatReloader
network_operator_container  | Performing system checks...
network_operator_container  | 
network_operator_container  | System check identified no issues (0 silenced).
network_operator_container  | August 05, 2024 - 16:40:31
network_operator_container  | Django version 3.2, using settings 'AEYE_Network_Operator.settings'
network_operator_container  | Starting development server at http://0.0.0.0:3000/
network_operator_container  | Quit the server with CONTROL-C.
network_operator_container  | 
network_operator_container  | -----------------------------------------
network_operator_container  | 2024-08-05 16:40:33 Yoonchul[ API - ANO ]
network_operator_container  | [AI NetOper - active] message: [ Received Valid Data : Request AI Inference, Inference ]
network_operator_container  | -----------------------------------------
network_operator_container  | Internal Server Error: /api/ai-network-operator/
network_operator_container  | Traceback (most recent call last):
network_operator_container  |   File "/usr/local/lib/python3.8/site-packages/django/core/handlers/exception.py", line 47, in inner
network_operator_container  |     response = get_response(request)
network_operator_container  |   File "/usr/local/lib/python3.8/site-packages/django/core/handlers/base.py", line 181, in _get_response
network_operator_container  |     response = wrapped_callback(request, *callback_args, **callback_kwargs)
network_operator_container  |   File "/usr/local/lib/python3.8/site-packages/django/views/decorators/csrf.py", line 54, in wrapped_view
network_operator_container  |     return view_func(*args, **kwargs)
network_operator_container  |   File "/usr/local/lib/python3.8/site-packages/rest_framework/viewsets.py", line 125, in view
network_operator_container  |     return self.dispatch(request, *args, **kwargs)
network_operator_container  |   File "/usr/local/lib/python3.8/site-packages/rest_framework/views.py", line 509, in dispatch
network_operator_container  |     response = self.handle_exception(exc)
network_operator_container  |   File "/usr/local/lib/python3.8/site-packages/rest_framework/views.py", line 469, in handle_exception
network_operator_container  |     self.raise_uncaught_exception(exc)
network_operator_container  |   File "/usr/local/lib/python3.8/site-packages/rest_framework/views.py", line 480, in raise_uncaught_exception
network_operator_container  |     raise exc
network_operator_container  |   File "/usr/local/lib/python3.8/site-packages/rest_framework/views.py", line 506, in dispatch
network_operator_container  |     response = handler(request, *args, **kwargs)
network_operator_container  |   File "/app/api/views/AEYE_ANO.py", line 46, in create
network_operator_container  |     response = aeye_ai_inference_request(image, url)
network_operator_container  |   File "/app/api/views/AEYE_ANO.py", line 76, in aeye_ai_inference_request
network_operator_container  |     print_log('active', whoami, api, "Send Data to : {}".format(url))
network_operator_container  | UnboundLocalError: local variable 'whoami' referenced before assignment
network_operator_container  | [05/Aug/2024 16:40:33] "POST /api/ai-network-operator/ HTTP/1.1" 500 94321
network_operator_container  | 
network_operator_container  | -----------------------------------------
network_operator_container  | 2024-08-05 16:40:51 Yoonchul[ API - ANO ]
network_operator_container  | [AI NetOper - active] message: [ Received Valid Data : Request AI Inference, Inference ]
network_operator_container  | -----------------------------------------
network_operator_container  | Internal Server Error: /api/ai-network-operator/
network_operator_container  | Traceback (most recent call last):
network_operator_container  |   File "/usr/local/lib/python3.8/site-packages/django/core/handlers/exception.py", line 47, in inner
network_operator_container  |     response = get_response(request)
network_operator_container  |   File "/usr/local/lib/python3.8/site-packages/django/core/handlers/base.py", line 181, in _get_response
network_operator_container  |     response = wrapped_callback(request, *callback_args, **callback_kwargs)
network_operator_container  |   File "/usr/local/lib/python3.8/site-packages/django/views/decorators/csrf.py", line 54, in wrapped_view
network_operator_container  |     return view_func(*args, **kwargs)
network_operator_container  |   File "/usr/local/lib/python3.8/site-packages/rest_framework/viewsets.py", line 125, in view
network_operator_container  |     return self.dispatch(request, *args, **kwargs)
network_operator_container  |   File "/usr/local/lib/python3.8/site-packages/rest_framework/views.py", line 509, in dispatch
network_operator_container  |     response = self.handle_exception(exc)
network_operator_container  |   File "/usr/local/lib/python3.8/site-packages/rest_framework/views.py", line 469, in handle_exception
network_operator_container  |     self.raise_uncaught_exception(exc)
network_operator_container  |   File "/usr/local/lib/python3.8/site-packages/rest_framework/views.py", line 480, in raise_uncaught_exception
network_operator_container  |     raise exc
network_operator_container  |   File "/usr/local/lib/python3.8/site-packages/rest_framework/views.py", line 506, in dispatch
network_operator_container  |     response = handler(request, *args, **kwargs)
network_operator_container  |   File "/app/api/views/AEYE_ANO.py", line 46, in create
network_operator_container  |     response = aeye_ai_inference_request(image, url)
network_operator_container  |   File "/app/api/views/AEYE_ANO.py", line 76, in aeye_ai_inference_request
network_operator_container  |     print_log('active', whoami, api, "Send Data to : {}".format(url))
network_operator_container  | UnboundLocalError: local variable 'whoami' referenced before assignment
network_operator_container  | [05/Aug/2024 16:40:51] "POST /api/ai-network-operator/ HTTP/1.1" 500 94377
network_operator_container  | /app/api/views/AEYE_ANO.py changed, reloading.
network_operator_container  | Watching for file changes with StatReloader
network_operator_container  | Performing system checks...
network_operator_container  | 
network_operator_container  | System check identified no issues (0 silenced).
network_operator_container  | August 05, 2024 - 16:41:11
network_operator_container  | Django version 3.2, using settings 'AEYE_Network_Operator.settings'
network_operator_container  | Starting development server at http://0.0.0.0:3000/
network_operator_container  | Quit the server with CONTROL-C.
network_operator_container  | 
network_operator_container  | -----------------------------------------
network_operator_container  | 2024-08-05 16:41:13 Yoonchul[ API - ANO ]
network_operator_container  | [AI NetOper - active] message: [ Received Valid Data : Request AI Inference, Oper: Inference ]
network_operator_container  | -----------------------------------------
network_operator_container  | Internal Server Error: /api/ai-network-operator/
network_operator_container  | Traceback (most recent call last):
network_operator_container  |   File "/usr/local/lib/python3.8/site-packages/django/core/handlers/exception.py", line 47, in inner
network_operator_container  |     response = get_response(request)
network_operator_container  |   File "/usr/local/lib/python3.8/site-packages/django/core/handlers/base.py", line 181, in _get_response
network_operator_container  |     response = wrapped_callback(request, *callback_args, **callback_kwargs)
network_operator_container  |   File "/usr/local/lib/python3.8/site-packages/django/views/decorators/csrf.py", line 54, in wrapped_view
network_operator_container  |     return view_func(*args, **kwargs)
network_operator_container  |   File "/usr/local/lib/python3.8/site-packages/rest_framework/viewsets.py", line 125, in view
network_operator_container  |     return self.dispatch(request, *args, **kwargs)
network_operator_container  |   File "/usr/local/lib/python3.8/site-packages/rest_framework/views.py", line 509, in dispatch
network_operator_container  |     response = self.handle_exception(exc)
network_operator_container  |   File "/usr/local/lib/python3.8/site-packages/rest_framework/views.py", line 469, in handle_exception
network_operator_container  |     self.raise_uncaught_exception(exc)
network_operator_container  |   File "/usr/local/lib/python3.8/site-packages/rest_framework/views.py", line 480, in raise_uncaught_exception
network_operator_container  |     raise exc
network_operator_container  |   File "/usr/local/lib/python3.8/site-packages/rest_framework/views.py", line 506, in dispatch
network_operator_container  |     response = handler(request, *args, **kwargs)
network_operator_container  |   File "/app/api/views/AEYE_ANO.py", line 46, in create
network_operator_container  |     response = aeye_ai_inference_request(image, url)
network_operator_container  |   File "/app/api/views/AEYE_ANO.py", line 76, in aeye_ai_inference_request
network_operator_container  |     print_log('active', whoami, api, "Send Data to : {}".format(url))
network_operator_container  | UnboundLocalError: local variable 'whoami' referenced before assignment
network_operator_container  | [05/Aug/2024 16:41:13] "POST /api/ai-network-operator/ HTTP/1.1" 500 94383
network_operator_container  | /app/api/views/AEYE_ANO.py changed, reloading.
network_operator_container  | Watching for file changes with StatReloader
network_operator_container  | Performing system checks...
network_operator_container  | 
network_operator_container  | System check identified no issues (0 silenced).
network_operator_container  | August 05, 2024 - 16:41:40
network_operator_container  | Django version 3.2, using settings 'AEYE_Network_Operator.settings'
network_operator_container  | Starting development server at http://0.0.0.0:3000/
network_operator_container  | Quit the server with CONTROL-C.
network_operator_container  | 
network_operator_container  | -----------------------------------------
network_operator_container  | 2024-08-05 16:41:53 Yoonchul[ API - ANO ]
network_operator_container  | [AI NetOper - active] message: [ Received Valid Data : Request AI Inference, Oper: Inference ]
network_operator_container  | -----------------------------------------
network_operator_container  | 
network_operator_container  | -----------------------------------------
network_operator_container  | 2024-08-05 16:41:53 Yoonchul[ API - ANO ]
network_operator_container  | [AI NetOper - active] message: [ !!! ]
network_operator_container  | -----------------------------------------
network_operator_container  | Internal Server Error: /api/ai-network-operator/
network_operator_container  | Traceback (most recent call last):
network_operator_container  |   File "/usr/local/lib/python3.8/site-packages/django/core/handlers/exception.py", line 47, in inner
network_operator_container  |     response = get_response(request)
network_operator_container  |   File "/usr/local/lib/python3.8/site-packages/django/core/handlers/base.py", line 181, in _get_response
network_operator_container  |     response = wrapped_callback(request, *callback_args, **callback_kwargs)
network_operator_container  |   File "/usr/local/lib/python3.8/site-packages/django/views/decorators/csrf.py", line 54, in wrapped_view
network_operator_container  |     return view_func(*args, **kwargs)
network_operator_container  |   File "/usr/local/lib/python3.8/site-packages/rest_framework/viewsets.py", line 125, in view
network_operator_container  |     return self.dispatch(request, *args, **kwargs)
network_operator_container  |   File "/usr/local/lib/python3.8/site-packages/rest_framework/views.py", line 509, in dispatch
network_operator_container  |     response = self.handle_exception(exc)
network_operator_container  |   File "/usr/local/lib/python3.8/site-packages/rest_framework/views.py", line 469, in handle_exception
network_operator_container  |     self.raise_uncaught_exception(exc)
network_operator_container  |   File "/usr/local/lib/python3.8/site-packages/rest_framework/views.py", line 480, in raise_uncaught_exception
network_operator_container  |     raise exc
network_operator_container  |   File "/usr/local/lib/python3.8/site-packages/rest_framework/views.py", line 506, in dispatch
network_operator_container  |     response = handler(request, *args, **kwargs)
network_operator_container  |   File "/app/api/views/AEYE_ANO.py", line 47, in create
network_operator_container  |     response = aeye_ai_inference_request(image, url)
network_operator_container  |   File "/app/api/views/AEYE_ANO.py", line 77, in aeye_ai_inference_request
network_operator_container  |     print_log('active', whoami, api, "Send Data to : {}".format(url))
network_operator_container  | UnboundLocalError: local variable 'whoami' referenced before assignment
network_operator_container  | [05/Aug/2024 16:41:53] "POST /api/ai-network-operator/ HTTP/1.1" 500 94382
network_operator_container  | 
network_operator_container  | -----------------------------------------
network_operator_container  | 2024-08-05 16:41:54 Yoonchul[ API - ANO ]
network_operator_container  | [AI NetOper - active] message: [ Received Valid Data : Request AI Inference, Oper: Inference ]
network_operator_container  | -----------------------------------------
network_operator_container  | 
network_operator_container  | -----------------------------------------
network_operator_container  | 2024-08-05 16:41:54 Yoonchul[ API - ANO ]
network_operator_container  | [AI NetOper - active] message: [ !!! ]
network_operator_container  | -----------------------------------------
network_operator_container  | Internal Server Error: /api/ai-network-operator/
network_operator_container  | Traceback (most recent call last):
network_operator_container  |   File "/usr/local/lib/python3.8/site-packages/django/core/handlers/exception.py", line 47, in inner
network_operator_container  |     response = get_response(request)
network_operator_container  |   File "/usr/local/lib/python3.8/site-packages/django/core/handlers/base.py", line 181, in _get_response
network_operator_container  |     response = wrapped_callback(request, *callback_args, **callback_kwargs)
network_operator_container  |   File "/usr/local/lib/python3.8/site-packages/django/views/decorators/csrf.py", line 54, in wrapped_view
network_operator_container  |     return view_func(*args, **kwargs)
network_operator_container  |   File "/usr/local/lib/python3.8/site-packages/rest_framework/viewsets.py", line 125, in view
network_operator_container  |     return self.dispatch(request, *args, **kwargs)
network_operator_container  |   File "/usr/local/lib/python3.8/site-packages/rest_framework/views.py", line 509, in dispatch
network_operator_container  |     response = self.handle_exception(exc)
network_operator_container  |   File "/usr/local/lib/python3.8/site-packages/rest_framework/views.py", line 469, in handle_exception
network_operator_container  |     self.raise_uncaught_exception(exc)
network_operator_container  |   File "/usr/local/lib/python3.8/site-packages/rest_framework/views.py", line 480, in raise_uncaught_exception
network_operator_container  |     raise exc
network_operator_container  |   File "/usr/local/lib/python3.8/site-packages/rest_framework/views.py", line 506, in dispatch
network_operator_container  |     response = handler(request, *args, **kwargs)
network_operator_container  |   File "/app/api/views/AEYE_ANO.py", line 47, in create
network_operator_container  |     response = aeye_ai_inference_request(image, url)
network_operator_container  |   File "/app/api/views/AEYE_ANO.py", line 77, in aeye_ai_inference_request
network_operator_container  |     print_log('active', whoami, api, "Send Data to : {}".format(url))
network_operator_container  | UnboundLocalError: local variable 'whoami' referenced before assignment
network_operator_container  | [05/Aug/2024 16:41:54] "POST /api/ai-network-operator/ HTTP/1.1" 500 94382
network_operator_container  | 
network_operator_container  | -----------------------------------------
network_operator_container  | 2024-08-05 16:42:04 Yoonchul[ API - ANO ]
network_operator_container  | [AI NetOper - active] message: [ Received Valid Data : Request AI Inference, Oper: Inference ]
network_operator_container  | -----------------------------------------
network_operator_container  | 
network_operator_container  | -----------------------------------------
network_operator_container  | 2024-08-05 16:42:04 Yoonchul[ API - ANO ]
network_operator_container  | [AI NetOper - active] message: [ !!! ]
network_operator_container  | -----------------------------------------
network_operator_container  | Internal Server Error: /api/ai-network-operator/
network_operator_container  | Traceback (most recent call last):
network_operator_container  |   File "/usr/local/lib/python3.8/site-packages/django/core/handlers/exception.py", line 47, in inner
network_operator_container  |     response = get_response(request)
network_operator_container  |   File "/usr/local/lib/python3.8/site-packages/django/core/handlers/base.py", line 181, in _get_response
network_operator_container  |     response = wrapped_callback(request, *callback_args, **callback_kwargs)
network_operator_container  |   File "/usr/local/lib/python3.8/site-packages/django/views/decorators/csrf.py", line 54, in wrapped_view
network_operator_container  |     return view_func(*args, **kwargs)
network_operator_container  |   File "/usr/local/lib/python3.8/site-packages/rest_framework/viewsets.py", line 125, in view
network_operator_container  |     return self.dispatch(request, *args, **kwargs)
network_operator_container  |   File "/usr/local/lib/python3.8/site-packages/rest_framework/views.py", line 509, in dispatch
network_operator_container  |     response = self.handle_exception(exc)
network_operator_container  |   File "/usr/local/lib/python3.8/site-packages/rest_framework/views.py", line 469, in handle_exception
network_operator_container  |     self.raise_uncaught_exception(exc)
network_operator_container  |   File "/usr/local/lib/python3.8/site-packages/rest_framework/views.py", line 480, in raise_uncaught_exception
network_operator_container  |     raise exc
network_operator_container  |   File "/usr/local/lib/python3.8/site-packages/rest_framework/views.py", line 506, in dispatch
network_operator_container  |     response = handler(request, *args, **kwargs)
network_operator_container  |   File "/app/api/views/AEYE_ANO.py", line 47, in create
network_operator_container  |   File "/app/api/views/AEYE_ANO.py", line 77, in aeye_ai_inference_request
network_operator_container  |     }
network_operator_container  | UnboundLocalError: local variable 'whoami' referenced before assignment
network_operator_container  | [05/Aug/2024 16:42:04] "POST /api/ai-network-operator/ HTTP/1.1" 500 91336
network_operator_container  | /app/api/views/AEYE_ANO.py changed, reloading.
network_operator_container  | Watching for file changes with StatReloader
network_operator_container  | Performing system checks...
network_operator_container  | 
network_operator_container  | System check identified no issues (0 silenced).
network_operator_container  | August 05, 2024 - 16:42:05
network_operator_container  | Django version 3.2, using settings 'AEYE_Network_Operator.settings'
network_operator_container  | Starting development server at http://0.0.0.0:3000/
network_operator_container  | Quit the server with CONTROL-C.
network_operator_container  | /app/api/views/AEYE_ANO.py changed, reloading.
network_operator_container  | Watching for file changes with StatReloader
network_operator_container  | Performing system checks...
network_operator_container  | 
network_operator_container  | System check identified no issues (0 silenced).
network_operator_container  | August 05, 2024 - 16:42:11
network_operator_container  | Django version 3.2, using settings 'AEYE_Network_Operator.settings'
network_operator_container  | Starting development server at http://0.0.0.0:3000/
network_operator_container  | Quit the server with CONTROL-C.
network_operator_container  | 
network_operator_container  | -----------------------------------------
network_operator_container  | 2024-08-05 16:42:12 Yoonchul[ API - ANO ]
network_operator_container  | [AI NetOper - active] message: [ Received Valid Data : Request AI Inference, Oper: Inference ]
network_operator_container  | -----------------------------------------
network_operator_container  | 
network_operator_container  | -----------------------------------------
network_operator_container  | 2024-08-05 16:42:12 Yoonchul[ API - ANO ]
network_operator_container  | [AI NetOper - active] message: [ !!! ]
network_operator_container  | -----------------------------------------
network_operator_container  | Internal Server Error: /api/ai-network-operator/
network_operator_container  | Traceback (most recent call last):
network_operator_container  |   File "/usr/local/lib/python3.8/site-packages/django/core/handlers/exception.py", line 47, in inner
network_operator_container  |     response = get_response(request)
network_operator_container  |   File "/usr/local/lib/python3.8/site-packages/django/core/handlers/base.py", line 181, in _get_response
network_operator_container  |     response = wrapped_callback(request, *callback_args, **callback_kwargs)
network_operator_container  |   File "/usr/local/lib/python3.8/site-packages/django/views/decorators/csrf.py", line 54, in wrapped_view
network_operator_container  |     return view_func(*args, **kwargs)
network_operator_container  |   File "/usr/local/lib/python3.8/site-packages/rest_framework/viewsets.py", line 125, in view
network_operator_container  |     return self.dispatch(request, *args, **kwargs)
network_operator_container  |   File "/usr/local/lib/python3.8/site-packages/rest_framework/views.py", line 509, in dispatch
network_operator_container  |     response = self.handle_exception(exc)
network_operator_container  |   File "/usr/local/lib/python3.8/site-packages/rest_framework/views.py", line 469, in handle_exception
network_operator_container  |     self.raise_uncaught_exception(exc)
network_operator_container  |   File "/usr/local/lib/python3.8/site-packages/rest_framework/views.py", line 480, in raise_uncaught_exception
network_operator_container  |     raise exc
network_operator_container  |   File "/usr/local/lib/python3.8/site-packages/rest_framework/views.py", line 506, in dispatch
network_operator_container  |     response = handler(request, *args, **kwargs)
network_operator_container  |   File "/app/api/views/AEYE_ANO.py", line 48, in create
network_operator_container  |     response = aeye_ai_inference_request(image, url)
network_operator_container  |   File "/app/api/views/AEYE_ANO.py", line 78, in aeye_ai_inference_request
network_operator_container  |     print_log('active', whoami, api, "Send Data to : {}".format(url))
network_operator_container  | UnboundLocalError: local variable 'whoami' referenced before assignment
network_operator_container  | [05/Aug/2024 16:42:12] "POST /api/ai-network-operator/ HTTP/1.1" 500 94308
network_operator_container  | /app/api/views/AEYE_ANO.py changed, reloading.
network_operator_container  | Watching for file changes with StatReloader
network_operator_container  | Performing system checks...
network_operator_container  | 
network_operator_container  | System check identified no issues (0 silenced).
network_operator_container  | August 05, 2024 - 16:42:34
network_operator_container  | Django version 3.2, using settings 'AEYE_Network_Operator.settings'
network_operator_container  | Starting development server at http://0.0.0.0:3000/
network_operator_container  | Quit the server with CONTROL-C.
network_operator_container  | 
network_operator_container  | -----------------------------------------
network_operator_container  | 2024-08-05 16:42:36 Yoonchul[ API - ANO ]
network_operator_container  | [AI NetOper - active] message: [ Received Valid Data : Request AI Inference, Oper: Inference ]
network_operator_container  | -----------------------------------------
network_operator_container  | Internal Server Error: /api/ai-network-operator/
network_operator_container  | Traceback (most recent call last):
network_operator_container  |   File "/usr/local/lib/python3.8/site-packages/django/core/handlers/exception.py", line 47, in inner
network_operator_container  |     response = get_response(request)
network_operator_container  |   File "/usr/local/lib/python3.8/site-packages/django/core/handlers/base.py", line 181, in _get_response
network_operator_container  |     response = wrapped_callback(request, *callback_args, **callback_kwargs)
network_operator_container  |   File "/usr/local/lib/python3.8/site-packages/django/views/decorators/csrf.py", line 54, in wrapped_view
network_operator_container  |     return view_func(*args, **kwargs)
network_operator_container  |   File "/usr/local/lib/python3.8/site-packages/rest_framework/viewsets.py", line 125, in view
network_operator_container  |     return self.dispatch(request, *args, **kwargs)
network_operator_container  |   File "/usr/local/lib/python3.8/site-packages/rest_framework/views.py", line 509, in dispatch
network_operator_container  |     response = self.handle_exception(exc)
network_operator_container  |   File "/usr/local/lib/python3.8/site-packages/rest_framework/views.py", line 469, in handle_exception
network_operator_container  |     self.raise_uncaught_exception(exc)
network_operator_container  |   File "/usr/local/lib/python3.8/site-packages/rest_framework/views.py", line 480, in raise_uncaught_exception
network_operator_container  |     raise exc
network_operator_container  |   File "/usr/local/lib/python3.8/site-packages/rest_framework/views.py", line 506, in dispatch
network_operator_container  |     response = handler(request, *args, **kwargs)
network_operator_container  |   File "/app/api/views/AEYE_ANO.py", line 47, in create
network_operator_container  |     response = aeye_ai_inference_request(image, url)
network_operator_container  |   File "/app/api/views/AEYE_ANO.py", line 74, in aeye_ai_inference_request
network_operator_container  |     print_log('active', whoami, api, '!!!')
network_operator_container  | UnboundLocalError: local variable 'whoami' referenced before assignment
network_operator_container  | [05/Aug/2024 16:42:37] "POST /api/ai-network-operator/ HTTP/1.1" 500 94087
network_operator_container  | /app/api/views/AEYE_ANO.py changed, reloading.
network_operator_container  | Watching for file changes with StatReloader
network_operator_container  | Performing system checks...
network_operator_container  | 
network_operator_container  | System check identified no issues (0 silenced).
network_operator_container  | August 05, 2024 - 16:42:51
network_operator_container  | Django version 3.2, using settings 'AEYE_Network_Operator.settings'
network_operator_container  | Starting development server at http://0.0.0.0:3000/
network_operator_container  | Quit the server with CONTROL-C.
network_operator_container  | 
network_operator_container  | -----------------------------------------
network_operator_container  | 2024-08-05 16:42:51 Yoonchul[ API - ANO ]
network_operator_container  | [AI NetOper - active] message: [ Received Valid Data : Request AI Inference, Oper: Inference ]
network_operator_container  | -----------------------------------------
network_operator_container  | 
network_operator_container  | -----------------------------------------
network_operator_container  | 2024-08-05 16:42:51 AA[ API - ANO ]
network_operator_container  | [AI NetOper - active] message: [ !!! ]
network_operator_container  | -----------------------------------------
network_operator_container  | Internal Server Error: /api/ai-network-operator/
network_operator_container  | Traceback (most recent call last):
network_operator_container  |   File "/usr/local/lib/python3.8/site-packages/django/core/handlers/exception.py", line 47, in inner
network_operator_container  |     response = get_response(request)
network_operator_container  |   File "/usr/local/lib/python3.8/site-packages/django/core/handlers/base.py", line 181, in _get_response
network_operator_container  |     response = wrapped_callback(request, *callback_args, **callback_kwargs)
network_operator_container  |   File "/usr/local/lib/python3.8/site-packages/django/views/decorators/csrf.py", line 54, in wrapped_view
network_operator_container  |     return view_func(*args, **kwargs)
network_operator_container  |   File "/usr/local/lib/python3.8/site-packages/rest_framework/viewsets.py", line 125, in view
network_operator_container  |     return self.dispatch(request, *args, **kwargs)
network_operator_container  |   File "/usr/local/lib/python3.8/site-packages/rest_framework/views.py", line 509, in dispatch
network_operator_container  |     response = self.handle_exception(exc)
network_operator_container  |   File "/usr/local/lib/python3.8/site-packages/rest_framework/views.py", line 469, in handle_exception
network_operator_container  |     self.raise_uncaught_exception(exc)
network_operator_container  |   File "/usr/local/lib/python3.8/site-packages/rest_framework/views.py", line 480, in raise_uncaught_exception
network_operator_container  |     raise exc
network_operator_container  |   File "/usr/local/lib/python3.8/site-packages/rest_framework/views.py", line 506, in dispatch
network_operator_container  |     response = handler(request, *args, **kwargs)
network_operator_container  |   File "/app/api/views/AEYE_ANO.py", line 47, in create
network_operator_container  |     response = aeye_ai_inference_request(image, url)
network_operator_container  |   File "/app/api/views/AEYE_ANO.py", line 79, in aeye_ai_inference_request
network_operator_container  |     print_log('active', whoami, api, "Send Data to : {}".format(url))
network_operator_container  | UnboundLocalError: local variable 'whoami' referenced before assignment
network_operator_container  | [05/Aug/2024 16:42:51] "POST /api/ai-network-operator/ HTTP/1.1" 500 94336
network_operator_container  | /app/api/views/AEYE_ANO.py changed, reloading.
network_operator_container  | Watching for file changes with StatReloader
network_operator_container  | Performing system checks...
network_operator_container  | 
network_operator_container  | System check identified no issues (0 silenced).
network_operator_container  | August 05, 2024 - 16:43:01
network_operator_container  | Django version 3.2, using settings 'AEYE_Network_Operator.settings'
network_operator_container  | Starting development server at http://0.0.0.0:3000/
network_operator_container  | Quit the server with CONTROL-C.
network_operator_container  | 
network_operator_container  | -----------------------------------------
network_operator_container  | 2024-08-05 16:43:02 Yoonchul[ API - ANO ]
network_operator_container  | [AI NetOper - active] message: [ Received Valid Data : Request AI Inference, Oper: Inference ]
network_operator_container  | -----------------------------------------
network_operator_container  | Internal Server Error: /api/ai-network-operator/
network_operator_container  | Traceback (most recent call last):
network_operator_container  |   File "/usr/local/lib/python3.8/site-packages/django/core/handlers/exception.py", line 47, in inner
network_operator_container  |     response = get_response(request)
network_operator_container  |   File "/usr/local/lib/python3.8/site-packages/django/core/handlers/base.py", line 181, in _get_response
network_operator_container  |     response = wrapped_callback(request, *callback_args, **callback_kwargs)
network_operator_container  |   File "/usr/local/lib/python3.8/site-packages/django/views/decorators/csrf.py", line 54, in wrapped_view
network_operator_container  |     return view_func(*args, **kwargs)
network_operator_container  |   File "/usr/local/lib/python3.8/site-packages/rest_framework/viewsets.py", line 125, in view
network_operator_container  |     return self.dispatch(request, *args, **kwargs)
network_operator_container  |   File "/usr/local/lib/python3.8/site-packages/rest_framework/views.py", line 509, in dispatch
network_operator_container  |     response = self.handle_exception(exc)
network_operator_container  |   File "/usr/local/lib/python3.8/site-packages/rest_framework/views.py", line 469, in handle_exception
network_operator_container  |     self.raise_uncaught_exception(exc)
network_operator_container  |   File "/usr/local/lib/python3.8/site-packages/rest_framework/views.py", line 480, in raise_uncaught_exception
network_operator_container  |     raise exc
network_operator_container  |   File "/usr/local/lib/python3.8/site-packages/rest_framework/views.py", line 506, in dispatch
network_operator_container  |     response = handler(request, *args, **kwargs)
network_operator_container  |   File "/app/api/views/AEYE_ANO.py", line 47, in create
network_operator_container  |     response = aeye_ai_inference_request(image, url)
network_operator_container  |   File "/app/api/views/AEYE_ANO.py", line 77, in aeye_ai_inference_request
network_operator_container  |     print_log('active', whoami, api, "Send Data to : {}".format(url))
network_operator_container  | UnboundLocalError: local variable 'whoami' referenced before assignment
network_operator_container  | [05/Aug/2024 16:43:02] "POST /api/ai-network-operator/ HTTP/1.1" 500 94307
network_operator_container  | /app/api/views/AEYE_ANO.py changed, reloading.
network_operator_container  | Watching for file changes with StatReloader
network_operator_container  | Performing system checks...
network_operator_container  | 
network_operator_container  | System check identified no issues (0 silenced).
network_operator_container  | August 05, 2024 - 16:43:15
network_operator_container  | Django version 3.2, using settings 'AEYE_Network_Operator.settings'
network_operator_container  | Starting development server at http://0.0.0.0:3000/
network_operator_container  | Quit the server with CONTROL-C.
network_operator_container  | 
network_operator_container  | -----------------------------------------
network_operator_container  | 2024-08-05 16:43:16 Yoonchul[ API - ANO ]
network_operator_container  | [AI NetOper - active] message: [ Received Valid Data : Request AI Inference, Oper: Inference ]
network_operator_container  | -----------------------------------------
network_operator_container  | 
network_operator_container  | -----------------------------------------
network_operator_container  | 2024-08-05 16:43:16 AA[ API - ANO ]
network_operator_container  | [AI NetOper - active] message: [ !!! ]
network_operator_container  | -----------------------------------------
network_operator_container  | Internal Server Error: /api/ai-network-operator/
network_operator_container  | Traceback (most recent call last):
network_operator_container  |   File "/usr/local/lib/python3.8/site-packages/django/core/handlers/exception.py", line 47, in inner
network_operator_container  |     response = get_response(request)
network_operator_container  |   File "/usr/local/lib/python3.8/site-packages/django/core/handlers/base.py", line 181, in _get_response
network_operator_container  |     response = wrapped_callback(request, *callback_args, **callback_kwargs)
network_operator_container  |   File "/usr/local/lib/python3.8/site-packages/django/views/decorators/csrf.py", line 54, in wrapped_view
network_operator_container  |     return view_func(*args, **kwargs)
network_operator_container  |   File "/usr/local/lib/python3.8/site-packages/rest_framework/viewsets.py", line 125, in view
network_operator_container  |     return self.dispatch(request, *args, **kwargs)
network_operator_container  |   File "/usr/local/lib/python3.8/site-packages/rest_framework/views.py", line 509, in dispatch
network_operator_container  |     response = self.handle_exception(exc)
network_operator_container  |   File "/usr/local/lib/python3.8/site-packages/rest_framework/views.py", line 469, in handle_exception
network_operator_container  |     self.raise_uncaught_exception(exc)
network_operator_container  |   File "/usr/local/lib/python3.8/site-packages/rest_framework/views.py", line 480, in raise_uncaught_exception
network_operator_container  |     raise exc
network_operator_container  |   File "/usr/local/lib/python3.8/site-packages/rest_framework/views.py", line 506, in dispatch
network_operator_container  |     response = handler(request, *args, **kwargs)
network_operator_container  |   File "/app/api/views/AEYE_ANO.py", line 47, in create
network_operator_container  |     response = aeye_ai_inference_request(image, url)
network_operator_container  |   File "/app/api/views/AEYE_ANO.py", line 79, in aeye_ai_inference_request
network_operator_container  |     print_log('active', whoami, api, "Send Data to : {}".format(url))
network_operator_container  | UnboundLocalError: local variable 'whoami' referenced before assignment
network_operator_container  | [05/Aug/2024 16:43:16] "POST /api/ai-network-operator/ HTTP/1.1" 500 94336
network_operator_container  | /app/api/views/AEYE_ANO.py changed, reloading.
network_operator_container  | Watching for file changes with StatReloader
network_operator_container  | Performing system checks...
network_operator_container  | 
network_operator_container  | System check identified no issues (0 silenced).
network_operator_container  | August 05, 2024 - 16:43:51
network_operator_container  | Django version 3.2, using settings 'AEYE_Network_Operator.settings'
network_operator_container  | Starting development server at http://0.0.0.0:3000/
network_operator_container  | Quit the server with CONTROL-C.
network_operator_container  | 
network_operator_container  | -----------------------------------------
network_operator_container  | 2024-08-05 16:43:52 Yoonchul[ API - ANO ]
network_operator_container  | [AI NetOper - active] message: [ Received Valid Data : Request AI Inference, Oper: Inference ]
network_operator_container  | -----------------------------------------
network_operator_container  | 
network_operator_container  | -----------------------------------------
network_operator_container  | 2024-08-05 16:43:52 Yoonchul[ API - ANO ]
network_operator_container  | [AI NetOper - active] message: [ Send Data to : 127.0.0.1:3000/mw/ai-inference/ ]
network_operator_container  | -----------------------------------------
network_operator_container  | Internal Server Error: /api/ai-network-operator/
network_operator_container  | Traceback (most recent call last):
network_operator_container  |   File "/usr/local/lib/python3.8/site-packages/django/core/handlers/exception.py", line 47, in inner
network_operator_container  |     response = get_response(request)
network_operator_container  |   File "/usr/local/lib/python3.8/site-packages/django/core/handlers/base.py", line 181, in _get_response
network_operator_container  |     response = wrapped_callback(request, *callback_args, **callback_kwargs)
network_operator_container  |   File "/usr/local/lib/python3.8/site-packages/django/views/decorators/csrf.py", line 54, in wrapped_view
network_operator_container  |     return view_func(*args, **kwargs)
network_operator_container  |   File "/usr/local/lib/python3.8/site-packages/rest_framework/viewsets.py", line 125, in view
network_operator_container  |     return self.dispatch(request, *args, **kwargs)
network_operator_container  |   File "/usr/local/lib/python3.8/site-packages/rest_framework/views.py", line 509, in dispatch
network_operator_container  |     response = self.handle_exception(exc)
network_operator_container  |   File "/usr/local/lib/python3.8/site-packages/rest_framework/views.py", line 469, in handle_exception
network_operator_container  |     self.raise_uncaught_exception(exc)
network_operator_container  |   File "/usr/local/lib/python3.8/site-packages/rest_framework/views.py", line 480, in raise_uncaught_exception
network_operator_container  |     raise exc
network_operator_container  |   File "/usr/local/lib/python3.8/site-packages/rest_framework/views.py", line 506, in dispatch
network_operator_container  |     response = handler(request, *args, **kwargs)
network_operator_container  |   File "/app/api/views/AEYE_ANO.py", line 47, in create
network_operator_container  |     response = aeye_ai_inference_request(whoami, image, url)
network_operator_container  |   File "/app/api/views/AEYE_ANO.py", line 80, in aeye_ai_inference_request
network_operator_container  |     response = requests.post(url, data=data, files=files)
network_operator_container  |   File "/usr/local/lib/python3.8/site-packages/requests/api.py", line 115, in post
network_operator_container  |     return request("post", url, data=data, json=json, **kwargs)
network_operator_container  |   File "/usr/local/lib/python3.8/site-packages/requests/api.py", line 59, in request
network_operator_container  |     return session.request(method=method, url=url, **kwargs)
network_operator_container  |   File "/usr/local/lib/python3.8/site-packages/requests/sessions.py", line 589, in request
network_operator_container  |     resp = self.send(prep, **send_kwargs)
network_operator_container  |   File "/usr/local/lib/python3.8/site-packages/requests/sessions.py", line 697, in send
network_operator_container  |     adapter = self.get_adapter(url=request.url)
network_operator_container  |   File "/usr/local/lib/python3.8/site-packages/requests/sessions.py", line 792, in get_adapter
network_operator_container  |     raise InvalidSchema(f"No connection adapters were found for {url!r}")
network_operator_container  | requests.exceptions.InvalidSchema: No connection adapters were found for '127.0.0.1:3000/mw/ai-inference/'
network_operator_container  | [05/Aug/2024 16:43:52] "POST /api/ai-network-operator/ HTTP/1.1" 500 133537
network_operator_container  | /app/api/views/AEYE_ANO.py changed, reloading.
network_operator_container  | Watching for file changes with StatReloader
network_operator_container  | Performing system checks...
network_operator_container  | 
network_operator_container  | System check identified no issues (0 silenced).
network_operator_container  | August 05, 2024 - 16:45:23
network_operator_container  | Django version 3.2, using settings 'AEYE_Network_Operator.settings'
network_operator_container  | Starting development server at http://0.0.0.0:3000/
network_operator_container  | Quit the server with CONTROL-C.
network_operator_container  | 
network_operator_container  | -----------------------------------------
network_operator_container  | 2024-08-05 16:45:26 Yoonchul[ API - ANO ]
network_operator_container  | [AI NetOper - active] message: [ Received Valid Data : Request AI Inference, Oper: Inference ]
network_operator_container  | -----------------------------------------
network_operator_container  | 
network_operator_container  | -----------------------------------------
network_operator_container  | 2024-08-05 16:45:26 Yoonchul[ API - ANO ]
network_operator_container  | [AI NetOper - active] message: [ Send Data to : http://127.0.0.1:3000/mw/ai-inference/ ]
network_operator_container  | -----------------------------------------
network_operator_container  | Bad Request: /mw/ai-inference/
network_operator_container  | [05/Aug/2024 16:45:26] "POST /mw/ai-inference/ HTTP/1.1" 400 75
network_operator_container  | Internal Server Error: /api/ai-network-operator/
network_operator_container  | Traceback (most recent call last):
network_operator_container  |   File "/usr/local/lib/python3.8/site-packages/django/core/handlers/exception.py", line 47, in inner
network_operator_container  |     response = get_response(request)
network_operator_container  |   File "/usr/local/lib/python3.8/site-packages/django/core/handlers/base.py", line 181, in _get_response
network_operator_container  |     response = wrapped_callback(request, *callback_args, **callback_kwargs)
network_operator_container  |   File "/usr/local/lib/python3.8/site-packages/django/views/decorators/csrf.py", line 54, in wrapped_view
network_operator_container  |     return view_func(*args, **kwargs)
network_operator_container  |   File "/usr/local/lib/python3.8/site-packages/rest_framework/viewsets.py", line 125, in view
network_operator_container  |     return self.dispatch(request, *args, **kwargs)
network_operator_container  |   File "/usr/local/lib/python3.8/site-packages/rest_framework/views.py", line 509, in dispatch
network_operator_container  |     response = self.handle_exception(exc)
network_operator_container  |   File "/usr/local/lib/python3.8/site-packages/rest_framework/views.py", line 469, in handle_exception
network_operator_container  |     self.raise_uncaught_exception(exc)
network_operator_container  |   File "/usr/local/lib/python3.8/site-packages/rest_framework/views.py", line 480, in raise_uncaught_exception
network_operator_container  |     raise exc
network_operator_container  |   File "/usr/local/lib/python3.8/site-packages/rest_framework/views.py", line 506, in dispatch
network_operator_container  |     response = handler(request, *args, **kwargs)
network_operator_container  |   File "/app/api/views/AEYE_ANO.py", line 47, in create
network_operator_container  |     response = aeye_ai_inference_request(whoami, image, url)
network_operator_container  |   File "/app/api/views/AEYE_ANO.py", line 89, in aeye_ai_inference_request
network_operator_container  |     print_log('error', whoami, api, "Failed to Receive Data : {}".format(message) )
network_operator_container  | UnboundLocalError: local variable 'message' referenced before assignment
network_operator_container  | [05/Aug/2024 16:45:26] "POST /api/ai-network-operator/ HTTP/1.1" 500 94774
network_operator_container  | /app/api/views/AEYE_ANO.py changed, reloading.
network_operator_container  | Watching for file changes with StatReloader
network_operator_container  | Performing system checks...
network_operator_container  | 
network_operator_container  | System check identified no issues (0 silenced).
network_operator_container  | August 05, 2024 - 16:47:14
network_operator_container  | Django version 3.2, using settings 'AEYE_Network_Operator.settings'
network_operator_container  | Starting development server at http://0.0.0.0:3000/
network_operator_container  | Quit the server with CONTROL-C.
network_operator_container  | 
network_operator_container  | -----------------------------------------
network_operator_container  | 2024-08-05 16:47:14 Yoonchul[ API - ANO ]
network_operator_container  | [AI NetOper - active] message: [ Received Valid Data : Request AI Inference, Oper: Inference ]
network_operator_container  | -----------------------------------------
network_operator_container  | 
network_operator_container  | -----------------------------------------
network_operator_container  | 2024-08-05 16:47:14 Yoonchul[ API - ANO ]
network_operator_container  | [AI NetOper - active] message: [ Send Data to : http://127.0.0.1:3000/mw/ai-inference/ ]
network_operator_container  | -----------------------------------------
network_operator_container  | Bad Request: /mw/ai-inference/
network_operator_container  | [05/Aug/2024 16:47:14] "POST /mw/ai-inference/ HTTP/1.1" 400 75
network_operator_container  | Internal Server Error: /api/ai-network-operator/
network_operator_container  | Traceback (most recent call last):
network_operator_container  |   File "/usr/local/lib/python3.8/site-packages/django/core/handlers/exception.py", line 47, in inner
network_operator_container  |     response = get_response(request)
network_operator_container  |   File "/usr/local/lib/python3.8/site-packages/django/core/handlers/base.py", line 181, in _get_response
network_operator_container  |     response = wrapped_callback(request, *callback_args, **callback_kwargs)
network_operator_container  |   File "/usr/local/lib/python3.8/site-packages/django/views/decorators/csrf.py", line 54, in wrapped_view
network_operator_container  |     return view_func(*args, **kwargs)
network_operator_container  |   File "/usr/local/lib/python3.8/site-packages/rest_framework/viewsets.py", line 125, in view
network_operator_container  |     return self.dispatch(request, *args, **kwargs)
network_operator_container  |   File "/usr/local/lib/python3.8/site-packages/rest_framework/views.py", line 509, in dispatch
network_operator_container  |     response = self.handle_exception(exc)
network_operator_container  |   File "/usr/local/lib/python3.8/site-packages/rest_framework/views.py", line 469, in handle_exception
network_operator_container  |     self.raise_uncaught_exception(exc)
network_operator_container  |   File "/usr/local/lib/python3.8/site-packages/rest_framework/views.py", line 480, in raise_uncaught_exception
network_operator_container  |     raise exc
network_operator_container  |   File "/usr/local/lib/python3.8/site-packages/rest_framework/views.py", line 506, in dispatch
network_operator_container  |     response = handler(request, *args, **kwargs)
network_operator_container  |   File "/app/api/views/AEYE_ANO.py", line 47, in create
network_operator_container  |     response = aeye_ai_inference_request(whoami, image, url)
network_operator_container  |   File "/app/api/views/AEYE_ANO.py", line 91, in aeye_ai_inference_request
network_operator_container  |     print_log('error', whoami, api, "Failed to Receive Data : {}".format(message) )
network_operator_container  | UnboundLocalError: local variable 'message' referenced before assignment
network_operator_container  | [05/Aug/2024 16:47:15] "POST /api/ai-network-operator/ HTTP/1.1" 500 94741
network_operator_container  | /app/api/views/AEYE_ANO.py changed, reloading.
network_operator_container  | Watching for file changes with StatReloader
network_operator_container  | Performing system checks...
network_operator_container  | 
network_operator_container  | System check identified no issues (0 silenced).
network_operator_container  | August 05, 2024 - 16:48:42
network_operator_container  | Django version 3.2, using settings 'AEYE_Network_Operator.settings'
network_operator_container  | Starting development server at http://0.0.0.0:3000/
network_operator_container  | Quit the server with CONTROL-C.
network_operator_container  | /app/api/views/AEYE_ANO.py changed, reloading.
network_operator_container  | Watching for file changes with StatReloader
network_operator_container  | Performing system checks...
network_operator_container  | 
network_operator_container  | System check identified no issues (0 silenced).
network_operator_container  | August 05, 2024 - 16:49:12
network_operator_container  | Django version 3.2, using settings 'AEYE_Network_Operator.settings'
network_operator_container  | Starting development server at http://0.0.0.0:3000/
network_operator_container  | Quit the server with CONTROL-C.
network_operator_container  | 
network_operator_container  | -----------------------------------------
network_operator_container  | 2024-08-05 16:49:14 Yoonchul[ API - ANO ]
network_operator_container  | [AI NetOper - active] message: [ Received Valid Data : Request AI Inference, Oper: Inference ]
network_operator_container  | -----------------------------------------
network_operator_container  | 
network_operator_container  | -----------------------------------------
network_operator_container  | 2024-08-05 16:49:14 Yoonchul[ API - ANO ]
network_operator_container  | [AI NetOper - active] message: [ Send Data to : http://127.0.0.1:3000/mw/ai-inference/ ]
network_operator_container  | -----------------------------------------
network_operator_container  | Bad Request: /mw/ai-inference/
network_operator_container  | [05/Aug/2024 16:49:14] "POST /mw/ai-inference/ HTTP/1.1" 400 75
network_operator_container  | 
network_operator_container  | -----------------------------------------
network_operator_container  | 2024-08-05 16:49:14 Yoonchul[ API - ANO ]
network_operator_container  | [AI NetOper - error] message: [ Failed to Receive Data : Failed to Receive Data [NetOper - ANO] ]
network_operator_container  | -----------------------------------------
network_operator_container  | Internal Server Error: /api/ai-network-operator/
network_operator_container  | Traceback (most recent call last):
network_operator_container  |   File "/usr/local/lib/python3.8/site-packages/django/core/handlers/exception.py", line 47, in inner
network_operator_container  |     response = get_response(request)
network_operator_container  |   File "/usr/local/lib/python3.8/site-packages/django/core/handlers/base.py", line 181, in _get_response
network_operator_container  |     response = wrapped_callback(request, *callback_args, **callback_kwargs)
network_operator_container  |   File "/usr/local/lib/python3.8/site-packages/django/views/decorators/csrf.py", line 54, in wrapped_view
network_operator_container  |     return view_func(*args, **kwargs)
network_operator_container  |   File "/usr/local/lib/python3.8/site-packages/rest_framework/viewsets.py", line 125, in view
network_operator_container  |     return self.dispatch(request, *args, **kwargs)
network_operator_container  |   File "/usr/local/lib/python3.8/site-packages/rest_framework/views.py", line 509, in dispatch
network_operator_container  |     response = self.handle_exception(exc)
network_operator_container  |   File "/usr/local/lib/python3.8/site-packages/rest_framework/views.py", line 469, in handle_exception
network_operator_container  |     self.raise_uncaught_exception(exc)
network_operator_container  |   File "/usr/local/lib/python3.8/site-packages/rest_framework/views.py", line 480, in raise_uncaught_exception
network_operator_container  |     raise exc
network_operator_container  |   File "/usr/local/lib/python3.8/site-packages/rest_framework/views.py", line 506, in dispatch
network_operator_container  |     response = handler(request, *args, **kwargs)
network_operator_container  |   File "/app/api/views/AEYE_ANO.py", line 49, in create
network_operator_container  |     if response.status_code==200:
network_operator_container  | AttributeError: 'int' object has no attribute 'status_code'
network_operator_container  | [05/Aug/2024 16:49:14] "POST /api/ai-network-operator/ HTTP/1.1" 500 85447
network_operator_container  | /app/api/views/AEYE_ANO.py changed, reloading.
network_operator_container  | Watching for file changes with StatReloader
network_operator_container  | Performing system checks...
network_operator_container  | 
network_operator_container  | System check identified no issues (0 silenced).
network_operator_container  | August 05, 2024 - 16:50:46
network_operator_container  | Django version 3.2, using settings 'AEYE_Network_Operator.settings'
network_operator_container  | Starting development server at http://0.0.0.0:3000/
network_operator_container  | Quit the server with CONTROL-C.
network_operator_container  | 
network_operator_container  | -----------------------------------------
network_operator_container  | 2024-08-05 16:50:55 Yoonchul[ API - ANO ]
network_operator_container  | [AI NetOper - active] message: [ Received Valid Data : Request AI Inference, Oper: Inference ]
network_operator_container  | -----------------------------------------
network_operator_container  | 
network_operator_container  | -----------------------------------------
network_operator_container  | 2024-08-05 16:50:55 Yoonchul[ API - ANO ]
network_operator_container  | [AI NetOper - active] message: [ Send Data to : http://127.0.0.1:3000/mw/ai-inference/ ]
network_operator_container  | -----------------------------------------
network_operator_container  | Bad Request: /mw/ai-inference/
network_operator_container  | 
network_operator_container  | -----------------------------------------
network_operator_container  | [05/Aug/2024 16:50:55] "POST /mw/ai-inference/ HTTP/1.1" 400 75
network_operator_container  | 2024-08-05 16:50:55 Yoonchul[ API - ANO ]
network_operator_container  | [AI NetOper - error] message: [ Failed to Receive Data : Failed to Receive Data [NetOper - ANO] ]
network_operator_container  | -----------------------------------------
network_operator_container  | Bad Request: /api/ai-network-operator/
network_operator_container  | [05/Aug/2024 16:50:55] "POST /api/ai-network-operator/ HTTP/1.1" 400 76
network_operator_container  | /app/mw/views/AEYE_Inference.py changed, reloading.
network_operator_container  | Watching for file changes with StatReloader
network_operator_container  | Performing system checks...
network_operator_container  | 
network_operator_container  | System check identified no issues (0 silenced).
network_operator_container  | August 05, 2024 - 16:52:34
network_operator_container  | Django version 3.2, using settings 'AEYE_Network_Operator.settings'
network_operator_container  | Starting development server at http://0.0.0.0:3000/
network_operator_container  | Quit the server with CONTROL-C.
network_operator_container  | 
network_operator_container  | -----------------------------------------
network_operator_container  | 2024-08-05 16:52:35 Yoonchul[ API - ANO ]
network_operator_container  | [AI NetOper - active] message: [ Received Valid Data : Request AI Inference, Oper: Inference ]
network_operator_container  | -----------------------------------------
network_operator_container  | 
network_operator_container  | -----------------------------------------
network_operator_container  | 2024-08-05 16:52:35 Yoonchul[ API - ANO ]
network_operator_container  | [AI NetOper - active] message: [ Send Data to : http://127.0.0.1:3000/mw/ai-inference/ ]
network_operator_container  | -----------------------------------------
network_operator_container  | 
network_operator_container  | -----------------------------------------
network_operator_container  | 2024-08-05 16:52:35 MW - Inference[ MW - Inference ]
network_operator_container  | [AI NetOper - error] message: [ Failed to Received Data : <rest_framework.request.Request: POST '/mw/ai-inference/'> ]
network_operator_container  | -----------------------------------------
network_operator_container  | Bad Request: /mw/ai-inference/
network_operator_container  | [05/Aug/2024 16:52:35] "POST /mw/ai-inference/ HTTP/1.1" 400 75
network_operator_container  | 
network_operator_container  | -----------------------------------------
network_operator_container  | 2024-08-05 16:52:35 Yoonchul[ API - ANO ]
network_operator_container  | [AI NetOper - error] message: [ Failed to Receive Data : Failed to Receive Data [NetOper - ANO] ]
network_operator_container  | -----------------------------------------
network_operator_container  | Bad Request: /api/ai-network-operator/
network_operator_container  | [05/Aug/2024 16:52:35] "POST /api/ai-network-operator/ HTTP/1.1" 400 76
network_operator_container  | 
network_operator_container  | -----------------------------------------
network_operator_container  | 2024-08-05 16:52:44 Yoonchul[ API - ANO ]
network_operator_container  | [AI NetOper - active] message: [ Received Valid Data : Request AI Inference, Oper: Inference ]
network_operator_container  | -----------------------------------------
network_operator_container  | 
network_operator_container  | -----------------------------------------
network_operator_container  | 2024-08-05 16:52:44 Yoonchul[ API - ANO ]
network_operator_container  | [AI NetOper - active] message: [ Send Data to : http://127.0.0.1:3000/mw/ai-inference/ ]
network_operator_container  | -----------------------------------------
network_operator_container  | 
network_operator_container  | -----------------------------------------
network_operator_container  | 2024-08-05 16:52:44 MW - Inference[ MW - Inference ]
network_operator_container  | [AI NetOper - error] message: [ Failed to Received Data : <rest_framework.request.Request: POST '/mw/ai-inference/'> ]
network_operator_container  | -----------------------------------------
network_operator_container  | Bad Request: /mw/ai-inference/
network_operator_container  | 
network_operator_container  | -----------------------------------------
network_operator_container  | 2024-08-05 16:52:44 Yoonchul[ API - ANO ]
network_operator_container  | [05/Aug/2024 16:52:44] "POST /mw/ai-inference/ HTTP/1.1" 400 75
network_operator_container  | [AI NetOper - error] message: [ Failed to Receive Data : Failed to Receive Data [NetOper - ANO] ]
network_operator_container  | -----------------------------------------
network_operator_container  | Bad Request: /api/ai-network-operator/
network_operator_container  | [05/Aug/2024 16:52:44] "POST /api/ai-network-operator/ HTTP/1.1" 400 76
network_operator_container  | /app/mw/views/AEYE_Inference.py changed, reloading.
network_operator_container  | Watching for file changes with StatReloader
network_operator_container  | Performing system checks...
network_operator_container  | 
network_operator_container  | System check identified no issues (0 silenced).
network_operator_container  | August 05, 2024 - 16:52:44
network_operator_container  | Django version 3.2, using settings 'AEYE_Network_Operator.settings'
network_operator_container  | Starting development server at http://0.0.0.0:3000/
network_operator_container  | Quit the server with CONTROL-C.
network_operator_container  | 
network_operator_container  | -----------------------------------------
network_operator_container  | 2024-08-05 16:52:49 Yoonchul[ API - ANO ]
network_operator_container  | [AI NetOper - active] message: [ Received Valid Data : Request AI Inference, Oper: Inference ]
network_operator_container  | -----------------------------------------
network_operator_container  | 
network_operator_container  | -----------------------------------------
network_operator_container  | 2024-08-05 16:52:49 Yoonchul[ API - ANO ]
network_operator_container  | [AI NetOper - active] message: [ Send Data to : http://127.0.0.1:3000/mw/ai-inference/ ]
network_operator_container  | -----------------------------------------
network_operator_container  | 
network_operator_container  | -----------------------------------------
network_operator_container  | 2024-08-05 16:52:49 MW - Inference[ MW - Inference ]
network_operator_container  | [AI NetOper - error] message: [ Failed to Received Data : <QueryDict: {'whoami': ['AEYE NetOper ANO'], 'image': [<InMemoryUploadedFile: Untitled.png (image/png)>]}> ]
network_operator_container  | -----------------------------------------
network_operator_container  | Bad Request: /mw/ai-inference/
network_operator_container  | 
network_operator_container  | -----------------------------------------
network_operator_container  | 2024-08-05 16:52:49 Yoonchul[ API - ANO ]
network_operator_container  | [05/Aug/2024 16:52:49] "POST /mw/ai-inference/ HTTP/1.1" 400 75
network_operator_container  | [AI NetOper - error] message: [ Failed to Receive Data : Failed to Receive Data [NetOper - ANO] ]
network_operator_container  | -----------------------------------------
network_operator_container  | Bad Request: /api/ai-network-operator/
network_operator_container  | [05/Aug/2024 16:52:49] "POST /api/ai-network-operator/ HTTP/1.1" 400 76
network_operator_container  | /app/api/views/AEYE_ANO.py changed, reloading.
network_operator_container  | Watching for file changes with StatReloader
network_operator_container  | Performing system checks...
network_operator_container  | 
network_operator_container  | Exception in thread django-main-thread:
network_operator_container  | Traceback (most recent call last):
network_operator_container  |   File "/usr/local/lib/python3.8/threading.py", line 932, in _bootstrap_inner
network_operator_container  |     self.run()
network_operator_container  |   File "/usr/local/lib/python3.8/threading.py", line 870, in run
network_operator_container  |     self._target(*self._args, **self._kwargs)
network_operator_container  |   File "/usr/local/lib/python3.8/site-packages/django/utils/autoreload.py", line 64, in wrapper
network_operator_container  |     fn(*args, **kwargs)
network_operator_container  |   File "/usr/local/lib/python3.8/site-packages/django/core/management/commands/runserver.py", line 118, in inner_run
network_operator_container  |     self.check(display_num_errors=True)
network_operator_container  |   File "/usr/local/lib/python3.8/site-packages/django/core/management/base.py", line 419, in check
network_operator_container  |     all_issues = checks.run_checks(
network_operator_container  |   File "/usr/local/lib/python3.8/site-packages/django/core/checks/registry.py", line 76, in run_checks
network_operator_container  |     new_errors = check(app_configs=app_configs, databases=databases)
network_operator_container  |   File "/usr/local/lib/python3.8/site-packages/django/core/checks/urls.py", line 13, in check_url_config
network_operator_container  |     return check_resolver(resolver)
network_operator_container  |   File "/usr/local/lib/python3.8/site-packages/django/core/checks/urls.py", line 23, in check_resolver
network_operator_container  |     return check_method()
network_operator_container  |   File "/usr/local/lib/python3.8/site-packages/django/urls/resolvers.py", line 412, in check
network_operator_container  |     for pattern in self.url_patterns:
network_operator_container  |   File "/usr/local/lib/python3.8/site-packages/django/utils/functional.py", line 48, in __get__
network_operator_container  |     res = instance.__dict__[self.name] = self.func(instance)
network_operator_container  |   File "/usr/local/lib/python3.8/site-packages/django/urls/resolvers.py", line 598, in url_patterns
network_operator_container  |     patterns = getattr(self.urlconf_module, "urlpatterns", self.urlconf_module)
network_operator_container  |   File "/usr/local/lib/python3.8/site-packages/django/utils/functional.py", line 48, in __get__
network_operator_container  |     res = instance.__dict__[self.name] = self.func(instance)
network_operator_container  |   File "/usr/local/lib/python3.8/site-packages/django/urls/resolvers.py", line 591, in urlconf_module
network_operator_container  |     return import_module(self.urlconf_name)
network_operator_container  |   File "/usr/local/lib/python3.8/importlib/__init__.py", line 127, in import_module
network_operator_container  |     return _bootstrap._gcd_import(name[level:], package, level)
network_operator_container  |   File "<frozen importlib._bootstrap>", line 1014, in _gcd_import
network_operator_container  |   File "<frozen importlib._bootstrap>", line 991, in _find_and_load
network_operator_container  |   File "<frozen importlib._bootstrap>", line 975, in _find_and_load_unlocked
network_operator_container  |   File "<frozen importlib._bootstrap>", line 671, in _load_unlocked
network_operator_container  |   File "<frozen importlib._bootstrap_external>", line 843, in exec_module
network_operator_container  |   File "<frozen importlib._bootstrap>", line 219, in _call_with_frames_removed
network_operator_container  |   File "/app/AEYE_Network_Operator/urls.py", line 22, in <module>
network_operator_container  |     path('api/', include('api.urls')),
network_operator_container  |   File "/usr/local/lib/python3.8/site-packages/django/urls/conf.py", line 34, in include
network_operator_container  |     urlconf_module = import_module(urlconf_module)
network_operator_container  |   File "/usr/local/lib/python3.8/importlib/__init__.py", line 127, in import_module
network_operator_container  |     return _bootstrap._gcd_import(name[level:], package, level)
network_operator_container  |   File "<frozen importlib._bootstrap>", line 1014, in _gcd_import
network_operator_container  |   File "<frozen importlib._bootstrap>", line 991, in _find_and_load
network_operator_container  |   File "<frozen importlib._bootstrap>", line 975, in _find_and_load_unlocked
network_operator_container  |   File "<frozen importlib._bootstrap>", line 671, in _load_unlocked
network_operator_container  |   File "<frozen importlib._bootstrap_external>", line 843, in exec_module
network_operator_container  |   File "<frozen importlib._bootstrap>", line 219, in _call_with_frames_removed
network_operator_container  |   File "/app/api/urls.py", line 5, in <module>
network_operator_container  |     from .views.AEYE_ANO import aeye_ano_Viewsets
network_operator_container  |   File "/app/api/views/AEYE_ANO.py", line 76
network_operator_container  |     'message' : 'Request AI Inference'
network_operator_container  |               ^
network_operator_container  | SyntaxError: invalid syntax
network_operator_container  | /app/api/views/AEYE_ANO.py changed, reloading.
network_operator_container  | Watching for file changes with StatReloader
network_operator_container  | Performing system checks...
network_operator_container  | 
network_operator_container  | System check identified no issues (0 silenced).
network_operator_container  | August 05, 2024 - 16:54:24
network_operator_container  | Django version 3.2, using settings 'AEYE_Network_Operator.settings'
network_operator_container  | Starting development server at http://0.0.0.0:3000/
network_operator_container  | Quit the server with CONTROL-C.
network_operator_container  | 
network_operator_container  | -----------------------------------------
network_operator_container  | 2024-08-05 16:54:27 Yoonchul[ API - ANO ]
network_operator_container  | [AI NetOper - active] message: [ Received Valid Data : Request AI Inference, Oper: Inference ]
network_operator_container  | -----------------------------------------
network_operator_container  | 
network_operator_container  | -----------------------------------------
network_operator_container  | 2024-08-05 16:54:27 Yoonchul[ API - ANO ]
network_operator_container  | [AI NetOper - active] message: [ Send Data to : http://127.0.0.1:3000/mw/ai-inference/ ]
network_operator_container  | -----------------------------------------
network_operator_container  | 
network_operator_container  | -----------------------------------------
network_operator_container  | 2024-08-05 16:54:27 AEYE NetOper ANO[ MW - Inference ]
network_operator_container  | [AI NetOper - active] message: [ Succeed to Received Data : Request AI Inference ]
network_operator_container  | -----------------------------------------
network_operator_container  | 
network_operator_container  | -----------------------------------------
network_operator_container  | 2024-08-05 16:54:27 AEYE NetOper MW Inference[ MW - Inference ]
network_operator_container  | [AI NetOper - error] message: [ Failed to add image and h5 files to JSON files: [Errno 2] No such file or directory: '/app/mw/views/weight/Srinivasan2014.h5' ]
network_operator_container  | -----------------------------------------
network_operator_container  | 
network_operator_container  | -----------------------------------------
network_operator_container  | 2024-08-05 16:54:27 AEYE NetOper MW Inference[ MW - Inference ]
network_operator_container  | [AI NetOper - error] message: [ Failed to Create Data : 400 ]
network_operator_container  | -----------------------------------------
network_operator_container  | Bad Request: /mw/ai-inference/
network_operator_container  | 
network_operator_container  | -----------------------------------------
network_operator_container  | 2024-08-05 16:54:27 Yoonchul[ API - ANO ]
network_operator_container  | [05/Aug/2024 16:54:27] "POST /mw/ai-inference/ HTTP/1.1" 400 94
network_operator_container  | [AI NetOper - error] message: [ Failed to Receive Data : Failed to Receive Data [NetOper - ANO] ]
network_operator_container  | -----------------------------------------
network_operator_container  | Bad Request: /api/ai-network-operator/
network_operator_container  | [05/Aug/2024 16:54:27] "POST /api/ai-network-operator/ HTTP/1.1" 400 76
